Workbook
Name ACT: #REF!
Name ACTIVIDAD: #REF!
Name ADMINISTRACION: #REF!
Name AGRICULTURA: #REF!
Name AMORTBI: '[1]Bal1202-200603'!$U$226
Name AMORTBU: '[1]Bal1202-200603'!$U$225
Name BASEDATOS: #REF!
Name BOVINOS: #REF!
Name CAPRINOS: #REF!
Name COMBUSTIBLE: #REF!
Name EOAF: '[1]Bal1202-200603'!$E$10:$R$251
Name EOAF1: '[1]Bal1202-200603'!$R$10:$R$251
Name EST: #REF!
Name ESTADO: [2]LISTAS!$O$3:$O$6
Name ESTRUCTURA: #REF!
Name FORRAJE: #REF!
Name FR: #REF!
Name GANADERIA: #REF!
Name GENERAL: #REF!
Name IMPUESTOS: #REF!
Name INTERESES: #REF!
Name MAQUINARIA: #REF!
Name OVINO: #REF!
Name PORCINOS: #REF!
Name SEGUROS: #REF!
Name SEMILLAS: [3]!Tabla4[#All]
Name SOCIOS: #REF!
Name SUELDOS: #REF!
Name TIPO_FACT: [2]LISTAS!$S$3:$S$7

Sheet RESUMEN
A1: RESUMEN DE ACTIVIDADES 2025
A3: Etiquetas de fila | B3: Suma de EGRESOS | C3: Suma de INGRESOS | D3: Suma de EGRES USD | E3: Suma de INGRES USD
A4: ADMINISTRACION | B4: 38560494 | C4: 6437252.5 | D4: 26593.444 | E4: 4439.4845
A5: GASTOS_ADM | B5: 215693.81 | C5: 53700 | D5: 148.75435 | E5: 37.034483
A6: MANTENIMIENTO | B6: 0 | C6: 53700 | D6: 0 | E6: 37.034483
A7: SEGUROS | B7: 16134 | C7: 0 | D7: 11.126897 | E7: 0
A8: PLAN DE PAGOS | B8: 199559.81 | C8: 0 | D8: 137.62746 | E8: 0
A9: GASTOS_BANC | B9: 1654959.7 | C9: 13287.53 | D9: 1141.3515 | E9: 9.1638138
A10: COMISIONES | B10: 462413.68 | C10: 0 | D10: 318.90599 | E10: 0
A11: IMPUESTOS | B11: 1192546 | C11: 13287.53 | D11: 822.44554 | E11: 9.1638138
A12: GASTOS_FIN | B12: 2638047 | C12: 0 | D12: 1819.3428 | E12: 0
A13: INTERESES | B13: 2638047 | C13: 0 | D13: 1819.3428 | E13: 0
A14: PERSONAL | B14: 9732583.7 | C14: 0 | D14: 6712.1267 | E14: 0
A15: JORNALES | B15: 3149421 | C15: 0 | D15: 2172.0145 | E15: 0
... A69: Total general | B69: 2.3365279e+08 | C69: 2.2952879e+08 | D69: 161139.85 | E69: 158295.71

Sheet ACTIVIDADES
B1: IMPUTACION DE MONTOS DE LAS ACTIVIDADES PRODUCTIVAS 2025
B15: ACTIVIDADES | C15: ENERO | D15: FEBRERO | E15: MARZO | F15: ABRIL | G15: MAYO | H15: JUNIO | I15: JULIO | J15: AGOSTO | K15: SEPTIEMBRE | L15: OCTUBRE | M15: NOVIEMBRE | N15: DICIEMBRE | O15: TOTAL | P15: ESTIMADO | Q15: % | R15: USD | S15: USD/HA
B16: AGRICULTURA | C16: =SUM(C17,C18,C28) -> 3129704.7 | D16: =SUM(D17,D18,D28) -> 0 | E16: =SUM(E17,E18,E28) -> 0 | F16: =SUM(F17,F18,F28) -> 0 | G16: =SUM(G17,G18,G28) -> #REF! | H16: =SUM(H17,H18,H28) -> #REF! | I16: =SUM(I17,I18,I28) -> 0 | J16: =SUM(J17,J18,J28) -> 0 | ... N16: =SUM(N17,N18,N28) -> 0 | O16: =SUM(O17:O35) -> 3129704.7 | P16: =SUM(P17:P35) -> 3.4298105e+08 | Q16: =Tabla4[[#This Row],[TOTAL]]/Tabla4[[#This Row],[ESTIMADO]] -> 0.0091250075 | R16: =SUM(R17:R35) -> 296890.58
B17: ASESORAMIENTO | C17: =SUMIFS(Tabla3[[#All],[EGRESOS]],Tabla3[[#All],[PERIODO]],Tabla4[[#Headers],[ENERO]],Tabla3[[#All],[ACTIVIDAD]],ACTIVIDADES!$B$16,Tabla3[[#All],[CONCEPTO]],Tabla4[[#This Row],[ACTIVIDADES]]) -> 0 | D17: =SUMIFS(Tabla3[[#All],[EGRESOS]],Tabla3[[#All],[PERIODO]],Tabla4[[#Headers],[FEBRERO]],Tabla3[[#All],[ACTIVIDAD]],ACTIVIDADES!$B$16,Tabla3[[#All],[CONCEPTO]],Tabla4[[#This Row],[ACTIVIDADES]]) -> 0 | E17: =SUMIFS(Tabla3[[#All],[EGRESOS]],Tabla3[[#All],[PERIODO]],Tabla4[[#Headers],[MARZO]],Tabla3[[#All],[ACTIVIDAD]],ACTIVIDADES!$B$16,Tabla3[[#All],[CONCEPTO]],Tabla4[[#This Row],[ACTIVIDADES]]) -> 0 | F17: =SUMIFS(Tabla3[[#All],[EGRESOS]],Tabla3[[#All],[PERIODO]],Tabla4[[#Headers],[ABRIL]],Tabla3[[#All],[ACTIVIDAD]],ACTIVIDADES!$B$16,Tabla3[[#All],[CONCEPTO]],Tabla4[[#This Row],[ACTIVIDADES]]) -> 0 | G17: =SUMIFS(Tabla3[[#All],[EGRESOS]],Tabla3[[#All],[PERIODO]],Tabla4[[#Headers],[MAYO]],Tabla3[[#All],[ACTIVIDAD]],ACTIVIDADES!$B$16,Tabla3[[#All],[CONCEPTO]],Tabla4[[#This Row],[ACTIVIDADES]]) -> 0 | H17: =SUMIFS(Tabla3[[#All],[EGRESOS]],Tabla3[[#All],[PERIODO]],Tabla4[[#Headers],[JUNIO]],Tabla3[[#All],[ACTIVIDAD]],ACTIVIDADES!$B$16,Tabla3[[#All],[CONCEPTO]],Tabla4[[#This Row],[ACTIVIDADES]]) -> 0 | I17: =SUMIFS(Tabla3[[#All],[EGRESOS]],Tabla3[[#All],[PERIODO]],Tabla4[[#Headers],[JULIO]],Tabla3[[#All],[ACTIVIDAD]],ACTIVIDADES!$B$16,Tabla3[[#All],[CONCEPTO]],Tabla4[[#This Row],[ACTIVIDADES]]) -> 0 | J17: =SUMIFS(Tabla3[[#All],[EGRESOS]],Tabla3[[#All],[PERIODO]],Tabla4[[#Headers],[AGOSTO]],Tabla3[[#All],[ACTIVIDAD]],ACTIVIDADES!$B$16,Tabla3[[#All],[CONCEPTO]],Tabla4[[#This Row],[ACTIVIDADES]]) -> 0 | K17: =SUMIFS(Tabla3[[#All],[EGRESOS]],Tabla3[[#All],[PERIODO]],Tabla4[[#Headers],[SEPTIEMBRE]],Tabla3[[#All],[ACTIVIDAD]],ACTIVIDADES!$B$16,Tabla3[[#All],[CONCEPTO]],Tabla4[[#This Row],[ACTIVIDADES]]) -> 0 | L17: =SUMIFS(Tabla3[[#All],[EGRESOS]],Tabla3[[#All],[PERIODO]],Tabla4[[#Headers],[OCTUBRE]],Tabla3[[#All],[ACTIVIDAD]],ACTIVIDADES!$B$16,Tabla3[[#All],[CONCEPTO]],Tabla4[[#This Row],[ACTIVIDADES]]) -> 0 | O17: =SUM(Tabla4[[#This Row],[ENERO]:[DICIEMBRE]]) -> 0 | P17: 7826025 | Q17: =Tabla4[[#This Row],[TOTAL]]/Tabla4[[#This Row],[ESTIMADO]] -> 0 | R17: =Tabla4[[#This Row],[ESTIMADO]]/1140 -> 6864.9342 | S17: =Tabla4[[#This Row],[USD]]/(350) -> 19.614098
B18: SOJA | C18: =SUBTOTAL(109,C19:C27) -> 3129704.7 | D18: =SUBTOTAL(109,D19:D27) -> 0 | E18: =SUBTOTAL(109,E19:E27) -> 0 | F18: =SUBTOTAL(109,F19:F27) -> 0 | G18: =SUBTOTAL(109,G19:G27) -> #REF! | H18: =SUBTOTAL(109,H19:H27) -> #REF! | I18: =SUBTOTAL(109,I19:I27) -> 0 | J18: =SUBTOTAL(109,J19:J27) -> 0 | ... M18: =SUBTOTAL(109,M19:M27) -> 0 | N18: =SUBTOTAL(109,N19:N26) -> 0
B19: SIEMBRA | C19: =SUMIFS(Tabla3[[#All],[EGRESOS]],Tabla3[[#All],[PERIODO]],Tabla4[[#Headers],[ENERO]],Tabla3[[#All],[ACTIVIDAD]],ACTIVIDADES!$B$16,Tabla3[[#All],[CONCEPTO]],ACTIVIDADES!$B$18,Tabla3[[#All],[DETALLES]],Tabla4[[#This Row],[ACTIVIDADES]]) -> 0 | D19: =SUMIFS(Tabla3[EGRESOS],Tabla3[ACTIVIDAD],ACTIVIDADES!$B$18,Tabla3[PERIODO],Tabla4[[#Headers],[FEBRERO]],Tabla3[CONCEPTO],ACTIVIDADES!B16,Tabla3[DETALLES],Tabla4[[#This Row],[ACTIVIDADES]]) -> 0 | E19: =SUMIFS(Tabla3[[#All],[EGRESOS]],Tabla3[[#All],[PERIODO]],Tabla4[[#Headers],[MARZO]],Tabla3[[#All],[ACTIVIDAD]],ACTIVIDADES!B16,Tabla3[[#All],[CONCEPTO]],ACTIVIDADES!B18,Tabla3[[#All],[DETALLES]],Tabla4[[#This Row],[ACTIVIDADES]]) -> 0 | F19: =SUMIFS(Tabla3[[#All],[EGRESOS]],Tabla3[[#All],[PERIODO]],Tabla4[[#Headers],[ABRIL]],Tabla3[[#All],[ACTIVIDAD]],ACTIVIDADES!B16,Tabla3[[#All],[CONCEPTO]],ACTIVIDADES!B18,Tabla3[[#All],[DETALLES]],Tabla4[[#This Row],[ACTIVIDADES]]) -> 0 | G19: =SUMIFS(Tabla3[[#All],[EGRESOS]],Tabla3[[#All],[PERIODO]],Tabla4[[#Headers],[MAYO]],Tabla3[[#All],[ACTIVIDAD]],ACTIVIDADES!B16,Tabla3[[#All],[CONCEPTO]],ACTIVIDADES!B18,Tabla3[[#All],[DETALLES]],Tabla4[[#This Row],[ACTIVIDADES]]) -> 0 | H19: =SUMIFS(Tabla3[[#All],[EGRESOS]],Tabla3[[#All],[PERIODO]],Tabla4[[#Headers],[JUNIO]],Tabla3[[#All],[ACTIVIDAD]],ACTIVIDADES!B16,Tabla3[[#All],[CONCEPTO]],ACTIVIDADES!B18,Tabla3[[#All],[DETALLES]],Tabla4[[#This Row],[ACTIVIDADES]]) -> 0 | I19: =SUMIFS(Tabla3[[#All],[EGRESOS]],Tabla3[[#All],[PERIODO]],Tabla4[[#Headers],[JULIO]],Tabla3[[#All],[ACTIVIDAD]],ACTIVIDADES!B16,Tabla3[[#All],[CONCEPTO]],ACTIVIDADES!B18,Tabla3[[#All],[DETALLES]],Tabla4[[#This Row],[ACTIVIDADES]]) -> 0 | J19: =SUMIFS(Tabla3[[#All],[EGRESOS]],Tabla3[[#All],[PERIODO]],Tabla4[[#Headers],[AGOSTO]],Tabla3[[#All],[ACTIVIDAD]],ACTIVIDADES!B16,Tabla3[[#All],[CONCEPTO]],ACTIVIDADES!B18,Tabla3[[#All],[DETALLES]],Tabla4[[#This Row],[ACTIVIDADES]]) -> 0 | K19: =SUMIFS(Tabla3[[#All],[EGRESOS]],Tabla3[[#All],[PERIODO]],Tabla4[[#Headers],[SEPTIEMBRE]],Tabla3[[#All],[ACTIVIDAD]],ACTIVIDADES!B16,Tabla3[[#All],[CONCEPTO]],ACTIVIDADES!B18,Tabla3[[#All],[DETALLES]],B19) -> 0 | L19: =SUMIFS(Tabla3[[#All],[EGRESOS]],Tabla3[[#All],[PERIODO]],Tabla4[[#Headers],[OCTUBRE]],Tabla3[[#All],[ACTIVIDAD]],$B$16,Tabla3[[#All],[CONCEPTO]],$B$18,Tabla3[[#All],[DETALLES]],B19) -> 0 | M19: =SUMIFS(Tabla3[[#All],[EGRESOS]],Tabla3[[#All],[PERIODO]],Tabla4[[#Headers],[NOVIEMBRE]],Tabla3[[#All],[ACTIVIDAD]],$B$16,Tabla3[[#All],[CONCEPTO]],$B$18,Tabla3[[#All],[DETALLES]],B19) -> 0 | O19: =SUM(Tabla4[[#This Row],[ENERO]:[DICIEMBRE]]) -> 0 | P19: =14974524*1.21 -> 18119174 | Q19: =Tabla4[[#This Row],[TOTAL]]/Tabla4[[#This Row],[ESTIMADO]] -> 0 | R19: =Tabla4[[#This Row],[ESTIMADO]]/1140 -> 15894.012 | S19: =Tabla4[[#This Row],[USD]]/(350) -> 45.411464
B20: SEMILLAS | C20: =SUMIFS(Tabla3[[#All],[EGRESOS]],Tabla3[[#All],[PERIODO]],Tabla4[[#Headers],[ENERO]],Tabla3[[#All],[ACTIVIDAD]],ACTIVIDADES!$B$16,Tabla3[[#All],[CONCEPTO]],ACTIVIDADES!$B$18,Tabla3[[#All],[DETALLES]],Tabla4[[#This Row],[ACTIVIDADES]]) -> 0 | D20: =SUMIFS(Tabla3[EGRESOS],Tabla3[ACTIVIDAD],ACTIVIDADES!$B$16,Tabla3[PERIODO],Tabla4[[#Headers],[FEBRERO]],Tabla3[CONCEPTO],ACTIVIDADES!B18,Tabla3[DETALLES],Tabla4[[#This Row],[ACTIVIDADES]]) -> 0 | E20: =SUMIFS(Tabla3[[#All],[EGRESOS]],Tabla3[[#All],[PERIODO]],Tabla4[[#Headers],[MARZO]],Tabla3[[#All],[ACTIVIDAD]],ACTIVIDADES!B17,Tabla3[[#All],[CONCEPTO]],ACTIVIDADES!B18,Tabla3[[#All],[DETALLES]],Tabla4[[#This Row],[ACTIVIDADES]]) -> 0 | F20: =SUMIFS(Tabla3[[#All],[EGRESOS]],Tabla3[[#All],[PERIODO]],Tabla4[[#Headers],[ABRIL]],Tabla3[[#All],[ACTIVIDAD]],ACTIVIDADES!B16,Tabla3[[#All],[CONCEPTO]],ACTIVIDADES!B18,Tabla3[[#All],[DETALLES]],Tabla4[[#This Row],[ACTIVIDADES]]) -> 0 | G20: =SUMIFS(Tabla3[[#All],[EGRESOS]],Tabla3[[#All],[PERIODO]],Tabla4[[#Headers],[MAYO]],Tabla3[[#All],[ACTIVIDAD]],ACTIVIDADES!$B$16,Tabla3[[#All],[CONCEPTO]],ACTIVIDADES!$B$18,Tabla3[[#All],[DETALLES]],Tabla4[[#This Row],[ACTIVIDADES]]) -> 0 | H20: =SUMIFS(Tabla3[[#All],[EGRESOS]],Tabla3[[#All],[PERIODO]],Tabla4[[#Headers],[JUNIO]],Tabla3[[#All],[ACTIVIDAD]],ACTIVIDADES!B16,Tabla3[[#All],[CONCEPTO]],ACTIVIDADES!B18,Tabla3[[#All],[DETALLES]],Tabla4[[#This Row],[ACTIVIDADES]]) -> 0 | J20: =SUMIFS(Tabla3[[#All],[EGRESOS]],Tabla3[[#All],[PERIODO]],Tabla4[[#Headers],[AGOSTO]],Tabla3[[#All],[ACTIVIDAD]],ACTIVIDADES!B16,Tabla3[[#All],[CONCEPTO]],ACTIVIDADES!B18,Tabla3[[#All],[DETALLES]],Tabla4[[#This Row],[ACTIVIDADES]]) -> 0 | K20: =SUMIFS(Tabla3[[#All],[EGRESOS]],Tabla3[[#All],[PERIODO]],Tabla4[[#Headers],[SEPTIEMBRE]],Tabla3[[#All],[ACTIVIDAD]],ACTIVIDADES!B16,Tabla3[[#All],[CONCEPTO]],ACTIVIDADES!B18,Tabla3[[#All],[DETALLES]],B20) -> 0 | L20: =SUMIFS(Tabla3[[#All],[EGRESOS]],Tabla3[[#All],[PERIODO]],Tabla4[[#Headers],[OCTUBRE]],Tabla3[[#All],[ACTIVIDAD]],$B$16,Tabla3[[#All],[CONCEPTO]],$B$18,Tabla3[[#All],[DETALLES]],B20) -> 0 | M20: =SUMIFS(Tabla3[[#All],[EGRESOS]],Tabla3[[#All],[PERIODO]],Tabla4[[#Headers],[NOVIEMBRE]],Tabla3[[#All],[ACTIVIDAD]],$B$16,Tabla3[[#All],[CONCEPTO]],$B$18,Tabla3[[#All],[DETALLES]],B20) -> 0 | O20: =SUM(Tabla4[[#This Row],[ENERO]:[DICIEMBRE]]) -> 0 | P20: =Tabla4[[#This Row],[USD]]*1140 -> 11427280 | Q20: =Tabla4[[#This Row],[TOTAL]]/Tabla4[[#This Row],[ESTIMADO]] -> 0 | R20: 10023.93 | S20: =Tabla4[[#This Row],[USD]]/(350) -> 28.6398
B21: APLICACIONES | C21: =SUMIFS(Tabla3[[#All],[EGRESOS]],Tabla3[[#All],[PERIODO]],Tabla4[[#Headers],[ENERO]],Tabla3[[#All],[ACTIVIDAD]],ACTIVIDADES!$B$16,Tabla3[[#All],[CONCEPTO]],ACTIVIDADES!$B$18,Tabla3[[#All],[DETALLES]],Tabla4[[#This Row],[ACTIVIDADES]]) -> 3129704.7 | D21: =SUMIFS(Tabla3[EGRESOS],Tabla3[ACTIVIDAD],ACTIVIDADES!$B$16,Tabla3[PERIODO],Tabla4[[#Headers],[FEBRERO]],Tabla3[CONCEPTO],ACTIVIDADES!B18,Tabla3[DETALLES],Tabla4[[#This Row],[ACTIVIDADES]]) -> 0 | E21: =SUMIFS(Tabla3[[#All],[EGRESOS]],Tabla3[[#All],[PERIODO]],Tabla4[[#Headers],[MARZO]],Tabla3[[#All],[ACTIVIDAD]],ACTIVIDADES!$B$16,Tabla3[[#All],[CONCEPTO]],ACTIVIDADES!$B$18,Tabla3[[#All],[DETALLES]],Tabla4[[#This Row],[ACTIVIDADES]]) -> 0 | F21: =SUMIFS(Tabla3[[#All],[EGRESOS]],Tabla3[[#All],[PERIODO]],Tabla4[[#Headers],[ABRIL]],Tabla3[[#All],[ACTIVIDAD]],ACTIVIDADES!B16,Tabla3[[#All],[CONCEPTO]],ACTIVIDADES!B18,Tabla3[[#All],[DETALLES]],Tabla4[[#This Row],[ACTIVIDADES]]) -> 0 | G21: =SUMIFS(Tabla3[[#All],[EGRESOS]],Tabla3[[#All],[PERIODO]],Tabla4[[#Headers],[MAYO]],Tabla3[[#All],[ACTIVIDAD]],ACTIVIDADES!$B$16,Tabla3[[#All],[CONCEPTO]],ACTIVIDADES!$B$18,Tabla3[[#All],[DETALLES]],Tabla4[[#This Row],[ACTIVIDADES]]) -> 0 | H21: =SUMIFS(Tabla3[[#All],[EGRESOS]],Tabla3[[#All],[PERIODO]],Tabla4[[#Headers],[JUNIO]],Tabla3[[#All],[ACTIVIDAD]],ACTIVIDADES!$B$16,Tabla3[[#All],[CONCEPTO]],ACTIVIDADES!$B$18,Tabla3[[#All],[DETALLES]],Tabla4[[#This Row],[ACTIVIDADES]]) -> 0 | I21: =SUMIFS(Tabla3[[#All],[EGRESOS]],Tabla3[[#All],[PERIODO]],Tabla4[[#Headers],[JULIO]],Tabla3[[#All],[ACTIVIDAD]],ACTIVIDADES!$B$16,Tabla3[[#All],[CONCEPTO]],ACTIVIDADES!$B$18,Tabla3[[#All],[DETALLES]],Tabla4[[#This Row],[ACTIVIDADES]]) -> 0 | J21: =SUMIFS(Tabla3[[#All],[EGRESOS]],Tabla3[[#All],[PERIODO]],Tabla4[[#Headers],[AGOSTO]],Tabla3[[#All],[ACTIVIDAD]],ACTIVIDADES!B16,Tabla3[[#All],[CONCEPTO]],ACTIVIDADES!B18,Tabla3[[#All],[DETALLES]],Tabla4[[#This Row],[ACTIVIDADES]]) -> 0 | K21: =SUMIFS(Tabla3[[#All],[EGRESOS]],Tabla3[[#All],[PERIODO]],Tabla4[[#Headers],[SEPTIEMBRE]],Tabla3[[#All],[ACTIVIDAD]],ACTIVIDADES!B16,Tabla3[[#All],[CONCEPTO]],ACTIVIDADES!B18,Tabla3[[#All],[DETALLES]],B21) -> 0 | L21: =SUMIFS(Tabla3[[#All],[EGRESOS]],Tabla3[[#All],[PERIODO]],Tabla4[[#Headers],[OCTUBRE]],Tabla3[[#All],[ACTIVIDAD]],$B$16,Tabla3[[#All],[CONCEPTO]],$B$18,Tabla3[[#All],[DETALLES]],B21) -> 0 | M21: =SUMIFS(Tabla3[[#All],[EGRESOS]],Tabla3[[#All],[PERIODO]],Tabla4[[#Headers],[NOVIEMBRE]],Tabla3[[#All],[ACTIVIDAD]],$B$16,Tabla3[[#All],[CONCEPTO]],$B$18,Tabla3[[#All],[DETALLES]],B21) -> 0 | O21: =SUM(Tabla4[[#This Row],[ENERO]:[DICIEMBRE]]) -> 3129704.7 | P21: =Tabla4[[#This Row],[USD]]*1140 -> 17912683 | Q21: =Tabla4[[#This Row],[TOTAL]]/Tabla4[[#This Row],[ESTIMADO]] -> 0.17472004 | R21: 15712.88 | S21: =Tabla4[[#This Row],[USD]]/(350) -> 44.893943
B22: INSUMOS 2025 | C22: =SUMIFS(Tabla3[[#All],[EGRESOS]],Tabla3[[#All],[PERIODO]],Tabla4[[#Headers],[ENERO]],Tabla3[[#All],[ACTIVIDAD]],ACTIVIDADES!$B$16,Tabla3[[#All],[CONCEPTO]],ACTIVIDADES!$B$18,Tabla3[[#All],[DETALLES]],Tabla4[[#This Row],[ACTIVIDADES]]) -> 0 | D22: =SUMIFS(Tabla3[EGRESOS],Tabla3[ACTIVIDAD],ACTIVIDADES!$B$16,Tabla3[PERIODO],Tabla4[[#Headers],[FEBRERO]],Tabla3[CONCEPTO],ACTIVIDADES!B18,Tabla3[DETALLES],Tabla4[[#This Row],[ACTIVIDADES]]) -> 0 | E22: =SUMIFS(Tabla3[[#All],[EGRESOS]],Tabla3[[#All],[PERIODO]],Tabla4[[#Headers],[MARZO]],Tabla3[[#All],[ACTIVIDAD]],ACTIVIDADES!$B$16,Tabla3[[#All],[CONCEPTO]],ACTIVIDADES!$B$18,Tabla3[[#All],[DETALLES]],Tabla4[[#This Row],[ACTIVIDADES]]) -> 0 | F22: =SUMIFS(Tabla3[[#All],[EGRESOS]],Tabla3[[#All],[PERIODO]],Tabla4[[#Headers],[ABRIL]],Tabla3[[#All],[ACTIVIDAD]],ACTIVIDADES!B16,Tabla3[[#All],[CONCEPTO]],ACTIVIDADES!B18,Tabla3[[#All],[DETALLES]],Tabla4[[#This Row],[ACTIVIDADES]]) -> 0 | G22: =SUMIFS(Tabla3[[#All],[EGRESOS]],Tabla3[[#All],[PERIODO]],Tabla4[[#Headers],[MAYO]],Tabla3[[#All],[ACTIVIDAD]],ACTIVIDADES!$B$16,Tabla3[[#All],[CONCEPTO]],ACTIVIDADES!$B$18,Tabla3[[#All],[DETALLES]],Tabla4[[#This Row],[ACTIVIDADES]]) -> 0 | H22: =SUMIFS(Tabla3[[#All],[EGRESOS]],Tabla3[[#All],[PERIODO]],Tabla4[[#Headers],[JUNIO]],Tabla3[[#All],[ACTIVIDAD]],ACTIVIDADES!B16,Tabla3[[#All],[CONCEPTO]],ACTIVIDADES!B18,Tabla3[[#All],[DETALLES]],Tabla4[[#This Row],[ACTIVIDADES]]) -> 0 | I22: =SUMIFS(Tabla3[[#All],[EGRESOS]],Tabla3[[#All],[PERIODO]],Tabla4[[#Headers],[JULIO]],Tabla3[[#All],[ACTIVIDAD]],ACTIVIDADES!B16,Tabla3[[#All],[CONCEPTO]],ACTIVIDADES!B18,Tabla3[[#All],[DETALLES]],Tabla4[[#This Row],[ACTIVIDADES]]) -> 0 | J22: =SUMIFS(Tabla3[[#All],[EGRESOS]],Tabla3[[#All],[PERIODO]],Tabla4[[#Headers],[AGOSTO]],Tabla3[[#All],[ACTIVIDAD]],ACTIVIDADES!B16,Tabla3[[#All],[CONCEPTO]],ACTIVIDADES!B18,Tabla3[[#All],[DETALLES]],Tabla4[[#This Row],[ACTIVIDADES]]) -> 0 | K22: =SUMIFS(Tabla3[[#All],[EGRESOS]],Tabla3[[#All],[PERIODO]],Tabla4[[#Headers],[SEPTIEMBRE]],Tabla3[[#All],[ACTIVIDAD]],ACTIVIDADES!B16,Tabla3[[#All],[CONCEPTO]],ACTIVIDADES!B18,Tabla3[[#All],[DETALLES]],B22) -> 0 | L22: =SUMIFS(Tabla3[[#All],[EGRESOS]],Tabla3[[#All],[PERIODO]],Tabla4[[#Headers],[OCTUBRE]],Tabla3[[#All],[ACTIVIDAD]],$B$16,Tabla3[[#All],[CONCEPTO]],$B$18,Tabla3[[#All],[DETALLES]],B22) -> 0 | M22: =SUMIFS(Tabla3[[#All],[EGRESOS]],Tabla3[[#All],[PERIODO]],Tabla4[[#Headers],[NOVIEMBRE]],Tabla3[[#All],[ACTIVIDAD]],$B$16,Tabla3[[#All],[CONCEPTO]],$B$18,Tabla3[[#All],[DETALLES]],B22) -> 0 | O22: =SUM(Tabla4[[#This Row],[ENERO]:[DICIEMBRE]]) -> 0 | P22: 52777452 | Q22: =Tabla4[[#This Row],[TOTAL]]/Tabla4[[#This Row],[ESTIMADO]] -> 0 | R22: 47589.805 | S22: =Tabla4[[#This Row],[USD]]/(350) -> 135.97087
B23: FLETES | C23: =SUMIFS(Tabla3[[#All],[EGRESOS]],Tabla3[[#All],[PERIODO]],Tabla4[[#Headers],[ENERO]],Tabla3[[#All],[ACTIVIDAD]],ACTIVIDADES!$B$16,Tabla3[[#All],[CONCEPTO]],ACTIVIDADES!$B$18,Tabla3[[#All],[DETALLES]],Tabla4[[#This Row],[ACTIVIDADES]]) -> 0 | D23: =SUMIFS(Tabla3[EGRESOS],Tabla3[ACTIVIDAD],ACTIVIDADES!$B$16,Tabla3[PERIODO],Tabla4[[#Headers],[FEBRERO]],Tabla3[CONCEPTO],ACTIVIDADES!B18,Tabla3[DETALLES],Tabla4[[#This Row],[ACTIVIDADES]]) -> 0 | E23: =SUMIFS(Tabla3[[#All],[EGRESOS]],Tabla3[[#All],[PERIODO]],Tabla4[[#Headers],[MARZO]],Tabla3[[#All],[ACTIVIDAD]],ACTIVIDADES!$B$16,Tabla3[[#All],[CONCEPTO]],ACTIVIDADES!$B$18,Tabla3[[#All],[DETALLES]],Tabla4[[#This Row],[ACTIVIDADES]]) -> 0 | F23: =SUMIFS(Tabla3[[#All],[EGRESOS]],Tabla3[[#All],[PERIODO]],Tabla4[[#Headers],[ABRIL]],Tabla3[[#All],[ACTIVIDAD]],ACTIVIDADES!B16,Tabla3[[#All],[CONCEPTO]],ACTIVIDADES!B18,Tabla3[[#All],[DETALLES]],Tabla4[[#This Row],[ACTIVIDADES]]) -> 0 | G23: =SUMIFS(Tabla3[[#All],[EGRESOS]],Tabla3[[#All],[PERIODO]],Tabla4[[#Headers],[MAYO]],Tabla3[[#All],[ACTIVIDAD]],ACTIVIDADES!$B$16,Tabla3[[#All],[CONCEPTO]],ACTIVIDADES!$B$18,Tabla3[[#All],[DETALLES]],Tabla4[[#This Row],[ACTIVIDADES]]) -> 0 | H23: =SUMIFS(Tabla3[[#All],[EGRESOS]],Tabla3[[#All],[PERIODO]],Tabla4[[#Headers],[JUNIO]],Tabla3[[#All],[ACTIVIDAD]],ACTIVIDADES!B16,Tabla3[[#All],[CONCEPTO]],ACTIVIDADES!B18,Tabla3[[#All],[DETALLES]],Tabla4[[#This Row],[ACTIVIDADES]]) -> 0 | I23: =SUMIFS(Tabla3[[#All],[EGRESOS]],Tabla3[[#All],[PERIODO]],Tabla4[[#Headers],[JULIO]],Tabla3[[#All],[ACTIVIDAD]],ACTIVIDADES!B16,Tabla3[[#All],[CONCEPTO]],ACTIVIDADES!B18,Tabla3[[#All],[DETALLES]],Tabla4[[#This Row],[ACTIVIDADES]]) -> 0 | J23: =SUMIFS(Tabla3[[#All],[EGRESOS]],Tabla3[[#All],[PERIODO]],Tabla4[[#Headers],[AGOSTO]],Tabla3[[#All],[ACTIVIDAD]],ACTIVIDADES!B16,Tabla3[[#All],[CONCEPTO]],ACTIVIDADES!B18,Tabla3[[#All],[DETALLES]],Tabla4[[#This Row],[ACTIVIDADES]]) -> 0 | K23: =SUMIFS(Tabla3[[#All],[EGRESOS]],Tabla3[[#All],[PERIODO]],Tabla4[[#Headers],[SEPTIEMBRE]],Tabla3[[#All],[ACTIVIDAD]],ACTIVIDADES!B16,Tabla3[[#All],[CONCEPTO]],ACTIVIDADES!B18,Tabla3[[#All],[DETALLES]],B23) -> 0 | L23: =SUMIFS(Tabla3[[#All],[EGRESOS]],Tabla3[[#All],[PERIODO]],Tabla4[[#Headers],[OCTUBRE]],Tabla3[[#All],[ACTIVIDAD]],$B$16,Tabla3[[#All],[CONCEPTO]],$B$18,Tabla3[[#All],[DETALLES]],B23) -> 0 | M23: =SUMIFS(Tabla3[[#All],[EGRESOS]],Tabla3[[#All],[PERIODO]],Tabla4[[#Headers],[NOVIEMBRE]],Tabla3[[#All],[ACTIVIDAD]],$B$16,Tabla3[[#All],[CONCEPTO]],$B$18,Tabla3[[#All],[DETALLES]],B23) -> 0 | O23: =SUM(Tabla4[[#This Row],[ENERO]:[DICIEMBRE]]) -> 0 | P23: 37735800 | Q23: =Tabla4[[#This Row],[TOTAL]]/Tabla4[[#This Row],[ESTIMADO]] -> 0 | R23: =Tabla4[[#This Row],[ESTIMADO]]/1140 -> 33101.579 | S23: =Tabla4[[#This Row],[USD]]/(350) -> 94.575941
B24: DESYUYADOR | C24: =SUMIFS(Tabla3[[#All],[EGRESOS]],Tabla3[[#All],[PERIODO]],Tabla4[[#Headers],[ENERO]],Tabla3[[#All],[ACTIVIDAD]],ACTIVIDADES!$B$16,Tabla3[[#All],[CONCEPTO]],ACTIVIDADES!$B$18,Tabla3[[#All],[DETALLES]],Tabla4[[#This Row],[ACTIVIDADES]]) -> 0 | D24: =SUMIFS(Tabla3[EGRESOS],Tabla3[ACTIVIDAD],ACTIVIDADES!$B$16,Tabla3[PERIODO],Tabla4[[#Headers],[FEBRERO]],Tabla3[CONCEPTO],ACTIVIDADES!B18,Tabla3[DETALLES],Tabla4[[#This Row],[ACTIVIDADES]]) -> 0 | E24: =SUMIFS(Tabla3[[#All],[EGRESOS]],Tabla3[[#All],[PERIODO]],Tabla4[[#Headers],[MARZO]],Tabla3[[#All],[ACTIVIDAD]],ACTIVIDADES!$B$16,Tabla3[[#All],[CONCEPTO]],ACTIVIDADES!$B$18,Tabla3[[#All],[DETALLES]],Tabla4[[#This Row],[ACTIVIDADES]]) -> 0 | F24: =SUMIFS(Tabla3[[#All],[EGRESOS]],Tabla3[[#All],[PERIODO]],Tabla4[[#Headers],[ABRIL]],Tabla3[[#All],[ACTIVIDAD]],ACTIVIDADES!B16,Tabla3[[#All],[CONCEPTO]],ACTIVIDADES!B18,Tabla3[[#All],[DETALLES]],Tabla4[[#This Row],[ACTIVIDADES]]) -> 0 | G24: =SUMIFS(Tabla3[[#All],[EGRESOS]],Tabla3[[#All],[PERIODO]],Tabla4[[#Headers],[MAYO]],Tabla3[[#All],[ACTIVIDAD]],ACTIVIDADES!$B$16,Tabla3[[#All],[CONCEPTO]],ACTIVIDADES!$B$18,Tabla3[[#All],[DETALLES]],Tabla4[[#This Row],[ACTIVIDADES]]) -> 0 | H24: =SUMIFS(Tabla3[[#All],[EGRESOS]],Tabla3[[#All],[PERIODO]],Tabla4[[#Headers],[JUNIO]],Tabla3[[#All],[ACTIVIDAD]],ACTIVIDADES!B16,Tabla3[[#All],[CONCEPTO]],ACTIVIDADES!B18,Tabla3[[#All],[DETALLES]],Tabla4[[#This Row],[ACTIVIDADES]]) -> 0 | I24: =SUMIFS(Tabla3[[#All],[EGRESOS]],Tabla3[[#All],[PERIODO]],Tabla4[[#Headers],[JULIO]],Tabla3[[#All],[ACTIVIDAD]],ACTIVIDADES!B16,Tabla3[[#All],[CONCEPTO]],ACTIVIDADES!B18,Tabla3[[#All],[DETALLES]],Tabla4[[#This Row],[ACTIVIDADES]]) -> 0 | J24: =SUMIFS(Tabla3[[#All],[EGRESOS]],Tabla3[[#All],[PERIODO]],Tabla4[[#Headers],[AGOSTO]],Tabla3[[#All],[ACTIVIDAD]],ACTIVIDADES!B16,Tabla3[[#All],[CONCEPTO]],ACTIVIDADES!B18,Tabla3[[#All],[DETALLES]],Tabla4[[#This Row],[ACTIVIDADES]]) -> 0 | K24: =SUMIFS(Tabla3[[#All],[EGRESOS]],Tabla3[[#All],[PERIODO]],Tabla4[[#Headers],[SEPTIEMBRE]],Tabla3[[#All],[ACTIVIDAD]],ACTIVIDADES!B16,Tabla3[[#All],[CONCEPTO]],ACTIVIDADES!B18,Tabla3[[#All],[DETALLES]],B24) -> 0 | L24: =SUMIFS(Tabla3[[#All],[EGRESOS]],Tabla3[[#All],[PERIODO]],Tabla4[[#Headers],[OCTUBRE]],Tabla3[[#All],[ACTIVIDAD]],$B$16,Tabla3[[#All],[CONCEPTO]],$B$18,Tabla3[[#All],[DETALLES]],B24) -> 0 | M24: =SUMIFS(Tabla3[[#All],[EGRESOS]],Tabla3[[#All],[PERIODO]],Tabla4[[#Headers],[NOVIEMBRE]],Tabla3[[#All],[ACTIVIDAD]],$B$16,Tabla3[[#All],[CONCEPTO]],$B$18,Tabla3[[#All],[DETALLES]],B24) -> 0 | O24: =SUM(Tabla4[[#This Row],[ENERO]:[DICIEMBRE]]) -> 0 | P24: 1100000 | Q24: =Tabla4[[#This Row],[TOTAL]]/Tabla4[[#This Row],[ESTIMADO]] -> 0 | R24: =Tabla4[[#This Row],[ESTIMADO]]/1140 -> 964.91228 | S24: =Tabla4[[#This Row],[USD]]/(350) -> 2.7568922
B25: COSECHA 114 HAS | C25: =SUMIFS(Tabla3[[#All],[EGRESOS]],Tabla3[[#All],[PERIODO]],Tabla4[[#Headers],[ENERO]],Tabla3[[#All],[ACTIVIDAD]],ACTIVIDADES!$B$16,Tabla3[[#All],[CONCEPTO]],ACTIVIDADES!$B$18,Tabla3[[#All],[DETALLES]],Tabla4[[#This Row],[ACTIVIDADES]]) -> 0 | D25: =SUMIFS(Tabla3[EGRESOS],Tabla3[ACTIVIDAD],ACTIVIDADES!$B$16,Tabla3[PERIODO],Tabla4[[#Headers],[FEBRERO]],Tabla3[CONCEPTO],ACTIVIDADES!B18,Tabla3[DETALLES],Tabla4[[#This Row],[ACTIVIDADES]]) -> 0 | E25: =SUMIFS(Tabla3[[#All],[EGRESOS]],Tabla3[[#All],[PERIODO]],Tabla4[[#Headers],[MARZO]],Tabla3[[#All],[ACTIVIDAD]],ACTIVIDADES!$B$16,Tabla3[[#All],[CONCEPTO]],ACTIVIDADES!$B$18,Tabla3[[#All],[DETALLES]],Tabla4[[#This Row],[ACTIVIDADES]]) -> 0 | F25: =SUMIFS(Tabla3[[#All],[EGRESOS]],Tabla3[[#All],[PERIODO]],Tabla4[[#Headers],[ABRIL]],Tabla3[[#All],[ACTIVIDAD]],ACTIVIDADES!B16,Tabla3[[#All],[CONCEPTO]],ACTIVIDADES!B18,Tabla3[[#All],[DETALLES]],Tabla4[[#This Row],[ACTIVIDADES]]) -> 0 | G25: =SUMIFS(Tabla3[[#All],[EGRESOS]],Tabla3[[#All],[PERIODO]],Tabla4[[#Headers],[MAYO]],Tabla3[[#All],[ACTIVIDAD]],ACTIVIDADES!$B$16,Tabla3[[#All],[CONCEPTO]],ACTIVIDADES!$B$18,Tabla3[[#All],[DETALLES]],Tabla4[[#This Row],[ACTIVIDADES]]) -> 0 | H25: =SUMIFS(Tabla3[[#All],[EGRESOS]],Tabla3[[#All],[PERIODO]],Tabla4[[#Headers],[JUNIO]],Tabla3[[#All],[ACTIVIDAD]],ACTIVIDADES!$B$16,Tabla3[[#All],[CONCEPTO]],ACTIVIDADES!$B$18,Tabla3[[#All],[DETALLES]],Tabla4[[#This Row],[ACTIVIDADES]]) -> 0 | I25: =SUMIFS(Tabla3[[#All],[EGRESOS]],Tabla3[[#All],[PERIODO]],Tabla4[[#Headers],[JULIO]],Tabla3[[#All],[ACTIVIDAD]],ACTIVIDADES!B16,Tabla3[[#All],[CONCEPTO]],ACTIVIDADES!B18,Tabla3[[#All],[DETALLES]],Tabla4[[#This Row],[ACTIVIDADES]]) -> 0 | J25: =SUMIFS(Tabla3[[#All],[EGRESOS]],Tabla3[[#All],[PERIODO]],Tabla4[[#Headers],[AGOSTO]],Tabla3[[#All],[ACTIVIDAD]],ACTIVIDADES!B16,Tabla3[[#All],[CONCEPTO]],ACTIVIDADES!B18,Tabla3[[#All],[DETALLES]],Tabla4[[#This Row],[ACTIVIDADES]]) -> 0 | K25: =SUMIFS(Tabla3[[#All],[EGRESOS]],Tabla3[[#All],[PERIODO]],Tabla4[[#Headers],[SEPTIEMBRE]],Tabla3[[#All],[ACTIVIDAD]],ACTIVIDADES!B16,Tabla3[[#All],[CONCEPTO]],ACTIVIDADES!B18,Tabla3[[#All],[DETALLES]],B25) -> 0 | L25: =SUMIFS(Tabla3[[#All],[EGRESOS]],Tabla3[[#All],[PERIODO]],Tabla4[[#Headers],[OCTUBRE]],Tabla3[[#All],[ACTIVIDAD]],$B$16,Tabla3[[#All],[CONCEPTO]],$B$18,Tabla3[[#All],[DETALLES]],B25) -> 0 | M25: =SUMIFS(Tabla3[[#All],[EGRESOS]],Tabla3[[#All],[PERIODO]],Tabla4[[#Headers],[NOVIEMBRE]],Tabla3[[#All],[ACTIVIDAD]],$B$16,Tabla3[[#All],[CONCEPTO]],$B$18,Tabla3[[#All],[DETALLES]],B25) -> 0 | O25: =SUM(Tabla4[[#This Row],[ENERO]:[DICIEMBRE]]) -> 0 | P25: =Tabla4[[#This Row],[USD]]*1360 -> 37095360 | Q25: =Tabla4[[#This Row],[TOTAL]]/Tabla4[[#This Row],[ESTIMADO]] -> 0 | R25: 27276 | S25: =Tabla4[[#This Row],[USD]]/(350) -> 77.931429
B26: EXTRACCION | C26: =SUMIFS(Tabla3[[#All],[EGRESOS]],Tabla3[[#All],[PERIODO]],Tabla4[[#Headers],[ENERO]],Tabla3[[#All],[ACTIVIDAD]],ACTIVIDADES!$B$16,Tabla3[[#All],[CONCEPTO]],ACTIVIDADES!$B$18,Tabla3[[#All],[DETALLES]],Tabla4[[#This Row],[ACTIVIDADES]]) -> 0 | D26: =SUMIFS(Tabla3[EGRESOS],Tabla3[ACTIVIDAD],ACTIVIDADES!$B$16,Tabla3[PERIODO],Tabla4[[#Headers],[FEBRERO]],Tabla3[CONCEPTO],ACTIVIDADES!B19,Tabla3[DETALLES],Tabla4[[#This Row],[ACTIVIDADES]]) -> 0 | E26: =SUMIFS(Tabla3[[#All],[EGRESOS]],Tabla3[[#All],[PERIODO]],Tabla4[[#Headers],[MARZO]],Tabla3[[#All],[ACTIVIDAD]],ACTIVIDADES!$B$16,Tabla3[[#All],[CONCEPTO]],ACTIVIDADES!$B$18,Tabla3[[#All],[DETALLES]],Tabla4[[#This Row],[ACTIVIDADES]]) -> 0 | F26: =SUMIFS(Tabla3[[#All],[EGRESOS]],Tabla3[[#All],[PERIODO]],Tabla4[[#Headers],[ABRIL]],Tabla3[[#All],[ACTIVIDAD]],ACTIVIDADES!B17,Tabla3[[#All],[CONCEPTO]],ACTIVIDADES!B19,Tabla3[[#All],[DETALLES]],Tabla4[[#This Row],[ACTIVIDADES]]) -> 0 | G26: =SUMIFS(Tabla3[[#All],[EGRESOS]],Tabla3[[#All],[PERIODO]],Tabla4[[#Headers],[MAYO]],Tabla3[[#All],[ACTIVIDAD]],ACTIVIDADES!$B$16,Tabla3[[#All],[CONCEPTO]],ACTIVIDADES!$B$18,Tabla3[[#All],[DETALLES]],Tabla4[[#This Row],[ACTIVIDADES]]) -> 0 | H26: =SUMIFS(Tabla3[[#All],[EGRESOS]],Tabla3[[#All],[PERIODO]],Tabla4[[#Headers],[JUNIO]],Tabla3[[#All],[ACTIVIDAD]],ACTIVIDADES!$B$16,Tabla3[[#All],[CONCEPTO]],ACTIVIDADES!$B$18,Tabla3[[#All],[DETALLES]],Tabla4[[#This Row],[ACTIVIDADES]]) -> 0 | I26: =SUMIFS(Tabla3[[#All],[EGRESOS]],Tabla3[[#All],[PERIODO]],Tabla4[[#Headers],[JULIO]],Tabla3[[#All],[ACTIVIDAD]],ACTIVIDADES!B17,Tabla3[[#All],[CONCEPTO]],ACTIVIDADES!B19,Tabla3[[#All],[DETALLES]],Tabla4[[#This Row],[ACTIVIDADES]]) -> 0 | J26: =SUMIFS(Tabla3[[#All],[EGRESOS]],Tabla3[[#All],[PERIODO]],Tabla4[[#Headers],[AGOSTO]],Tabla3[[#All],[ACTIVIDAD]],ACTIVIDADES!B17,Tabla3[[#All],[CONCEPTO]],ACTIVIDADES!B19,Tabla3[[#All],[DETALLES]],Tabla4[[#This Row],[ACTIVIDADES]]) -> 0 | K26: =SUMIFS(Tabla3[[#All],[EGRESOS]],Tabla3[[#All],[PERIODO]],Tabla4[[#Headers],[SEPTIEMBRE]],Tabla3[[#All],[ACTIVIDAD]],ACTIVIDADES!B17,Tabla3[[#All],[CONCEPTO]],ACTIVIDADES!B19,Tabla3[[#All],[DETALLES]],B26) -> 0 | L26: =SUMIFS(Tabla3[[#All],[EGRESOS]],Tabla3[[#All],[PERIODO]],Tabla4[[#Headers],[OCTUBRE]],Tabla3[[#All],[ACTIVIDAD]],$B$16,Tabla3[[#All],[CONCEPTO]],$B$18,Tabla3[[#All],[DETALLES]],B26) -> 0 | M26: =SUMIFS(Tabla3[[#All],[EGRESOS]],Tabla3[[#All],[PERIODO]],Tabla4[[#Headers],[NOVIEMBRE]],Tabla3[[#All],[ACTIVIDAD]],$B$16,Tabla3[[#All],[CONCEPTO]],$B$18,Tabla3[[#All],[DETALLES]],B26) -> 0 | O26: =SUM(Tabla4[[#This Row],[ENERO]:[DICIEMBRE]]) -> 0 | P26: 3550000 | Q26: =Tabla4[[#This Row],[TOTAL]]/Tabla4[[#This Row],[ESTIMADO]] -> 0 | R26: =Tabla4[[#This Row],[ESTIMADO]]/1140 -> 3114.0351 | S26: =Tabla4[[#This Row],[USD]]/(350) -> 8.8972431
B27: SOJA P EXPELLER | C27: =SUMIFS(Tabla3[[#All],[FACTURA]],Tabla3[[#All],[RUBRO]],Tabla4[[#Headers],[ENERO]],Tabla3[[#All],[EGRESOS]],$B$16,Tabla3[[#All],[SALDO]],$B$18,Tabla3[[#All],[SALDO BANCO]],#REF!) -> 0 | D27: =SUMIFS(Tabla3[[#All],[RDS]],Tabla3[[#All],[CONCEPTO]],Tabla4[[#Headers],[FEBRERO]],Tabla3[[#All],[INGRESOS]],$B$16,Tabla3[[#All],[SALDO BANCO]],$B$18,Tabla3[[#All],[TC]],#REF!) -> 0 | E27: =SUMIFS(Tabla3[[#All],[SOCIO]],Tabla3[[#All],[DETALLES]],Tabla4[[#Headers],[MARZO]],Tabla3[[#All],[SALDO]],$B$16,Tabla3[[#All],[TC]],$B$18,Tabla3[[#All],[EGRES USD]],#REF!) -> 0 | F27: =SUMIFS(Tabla3[[#All],[CAMPAÑA]],Tabla3[[#All],[PROVEEDOR CLIENTE]],Tabla4[[#Headers],[ABRIL]],Tabla3[[#All],[SALDO BANCO]],$B$16,Tabla3[[#All],[EGRES USD]],$B$18,Tabla3[[#All],[INGRES USD]],#REF!) -> 0 | G27: =SUMIFS(#REF!,Tabla3[[#All],[FACTURA]],Tabla4[[#Headers],[MAYO]],Tabla3[[#All],[TC]],$B$16,Tabla3[[#All],[INGRES USD]],$B$18,Tabla3[[#All],[MONEDA]],#REF!) -> #REF! | H27: =SUMIFS(#REF!,Tabla3[[#All],[RDS]],Tabla4[[#Headers],[JUNIO]],Tabla3[[#All],[EGRES USD]],$B$16,Tabla3[[#All],[MONEDA]],$B$18,Tabla3[[#All],[CUENTA]],#REF!) -> #REF! | I27: =SUMIFS(Tabla3[[#All],[PERIODO]],Tabla3[[#All],[SOCIO]],Tabla4[[#Headers],[JULIO]],Tabla3[[#All],[INGRES USD]],$B$16,Tabla3[[#All],[CUENTA]],$B$18,Tabla3[[#All],[BANCO]],#REF!) -> 0 | J27: =SUMIFS(Tabla3[[#All],[FECHA]],Tabla3[[#All],[CAMPAÑA]],Tabla4[[#Headers],[AGOSTO]],Tabla3[[#All],[MONEDA]],$B$16,Tabla3[[#All],[BANCO]],$B$18,Tabla3[[#All],[ACTIVIDAD]],#REF!) -> 0 | K27: =SUMIFS(Tabla3[[#All],[DESCRIPCION]],#REF!,Tabla4[[#Headers],[SEPTIEMBRE]],Tabla3[[#All],[CUENTA]],$B$16,Tabla3[[#All],[ACTIVIDAD]],$B$18,Tabla3[[#All],[RUBRO]],#REF!) -> #REF! | L27: =SUMIFS(Tabla3[[#All],[N DE REFERENCIA]],#REF!,Tabla4[[#Headers],[OCTUBRE]],Tabla3[[#All],[BANCO]],$B$16,Tabla3[[#All],[RUBRO]],$B$18,Tabla3[[#All],[CONCEPTO]],A27) -> #REF! | M27: =SUMIFS(Tabla3[[#All],[EGRESOS]],Tabla3[[#All],[PERIODO]],Tabla4[[#Headers],[NOVIEMBRE]],Tabla3[[#All],[ACTIVIDAD]],$B$16,Tabla3[[#All],[CONCEPTO]],$B$18,Tabla3[[#All],[DETALLES]],B27) -> 0
B28: MAIZ | C28: =SUBTOTAL(109,C29:C37) -> 0 | D28: =SUBTOTAL(109,D29:D37) -> 0 | E28: =SUBTOTAL(109,E29:E37) -> 0 | F28: =SUBTOTAL(109,F29:F37) -> 0 | G28: =SUBTOTAL(109,G29:G37) -> 0 | H28: =SUBTOTAL(109,H29:H37) -> 0 | I28: =SUBTOTAL(109,I29:I37) -> 0 | J28: =SUBTOTAL(109,J29:J37) -> 0 | ... N28: =SUBTOTAL(109,N29:N37) -> 0
B29: SIEMBRA | C29: =SUMIFS(Tabla3[[#All],[EGRESOS]],Tabla3[[#All],[PERIODO]],Tabla4[[#Headers],[ENERO]],Tabla3[[#All],[ACTIVIDAD]],ACTIVIDADES!$B$16,Tabla3[[#All],[CONCEPTO]],ACTIVIDADES!$B$28,Tabla3[[#All],[DETALLES]],Tabla4[[#This Row],[ACTIVIDADES]]) -> 0 | D29: =SUMIFS(Tabla3[EGRESOS],Tabla3[ACTIVIDAD],ACTIVIDADES!$B$16,Tabla3[PERIODO],Tabla4[[#Headers],[FEBRERO]],Tabla3[CONCEPTO],ACTIVIDADES!B28,Tabla3[DETALLES],Tabla4[[#This Row],[ACTIVIDADES]]) -> 0 | E29: =SUMIFS(Tabla3[[#All],[EGRESOS]],Tabla3[[#All],[PERIODO]],Tabla4[[#Headers],[MARZO]],Tabla3[[#All],[ACTIVIDAD]],ACTIVIDADES!$B$16,Tabla3[[#All],[CONCEPTO]],ACTIVIDADES!$B$28,Tabla3[[#All],[DETALLES]],Tabla4[[#This Row],[ACTIVIDADES]]) -> 0 | F29: =SUMIFS(Tabla3[[#All],[EGRESOS]],Tabla3[[#All],[PERIODO]],Tabla4[[#Headers],[ABRIL]],Tabla3[[#All],[ACTIVIDAD]],ACTIVIDADES!B16,Tabla3[[#All],[CONCEPTO]],ACTIVIDADES!B28,Tabla3[[#All],[DETALLES]],Tabla4[[#This Row],[ACTIVIDADES]]) -> 0 | G29: =SUMIFS(Tabla3[[#All],[EGRESOS]],Tabla3[[#All],[PERIODO]],Tabla4[[#Headers],[MAYO]],Tabla3[[#All],[ACTIVIDAD]],ACTIVIDADES!$B$16,Tabla3[[#All],[CONCEPTO]],ACTIVIDADES!$B$28,Tabla3[[#All],[DETALLES]],Tabla4[[#This Row],[ACTIVIDADES]]) -> 0 | H29: =SUMIFS(Tabla3[[#All],[EGRESOS]],Tabla3[[#All],[PERIODO]],Tabla4[[#Headers],[JUNIO]],Tabla3[[#All],[ACTIVIDAD]],ACTIVIDADES!B16,Tabla3[[#All],[CONCEPTO]],ACTIVIDADES!B28,Tabla3[[#All],[DETALLES]],Tabla4[[#This Row],[ACTIVIDADES]]) -> 0 | I29: =SUMIFS(Tabla3[[#All],[EGRESOS]],Tabla3[[#All],[PERIODO]],Tabla4[[#Headers],[JULIO]],Tabla3[[#All],[ACTIVIDAD]],ACTIVIDADES!B16,Tabla3[[#All],[CONCEPTO]],ACTIVIDADES!B28,Tabla3[[#All],[DETALLES]],Tabla4[[#This Row],[ACTIVIDADES]]) -> 0 | J29: =SUMIFS(Tabla3[[#All],[EGRESOS]],Tabla3[[#All],[PERIODO]],Tabla4[[#Headers],[AGOSTO]],Tabla3[[#All],[ACTIVIDAD]],ACTIVIDADES!B16,Tabla3[[#All],[CONCEPTO]],ACTIVIDADES!B28,Tabla3[[#All],[DETALLES]],Tabla4[[#This Row],[ACTIVIDADES]]) -> 0 | K29: =SUMIFS(Tabla3[[#All],[EGRESOS]],Tabla3[[#All],[PERIODO]],Tabla4[[#Headers],[SEPTIEMBRE]],Tabla3[[#All],[ACTIVIDAD]],ACTIVIDADES!B16,Tabla3[[#All],[CONCEPTO]],ACTIVIDADES!B28,Tabla3[[#All],[DETALLES]],B29) -> 0 | L29: =SUMIFS(Tabla3[[#All],[EGRESOS]],Tabla3[[#All],[PERIODO]],Tabla4[[#Headers],[OCTUBRE]],Tabla3[[#All],[ACTIVIDAD]],$B$16,Tabla3[[#All],[CONCEPTO]],$B$28,Tabla3[[#All],[DETALLES]],B29) -> 0 | M29: =SUMIFS(Tabla3[[#All],[EGRESOS]],Tabla3[[#All],[PERIODO]],Tabla4[[#Headers],[NOVIEMBRE]],Tabla3[[#All],[ACTIVIDAD]],$B$16,Tabla3[[#All],[CONCEPTO]],$B$28,Tabla3[[#All],[DETALLES]],B29) -> 0 | O29: =SUM(Tabla4[[#This Row],[ENERO]:[DICIEMBRE]]) -> 0 | P29: =Tabla4[[#This Row],[USD]]*1140 -> 8508500 | Q29: =Tabla4[[#This Row],[TOTAL]]/Tabla4[[#This Row],[ESTIMADO]] -> 0 | R29: 7463.5965 | S29: =Tabla4[[#This Row],[USD]]/140 -> 53.311404
B30: SEMILLAS | C30: =SUMIFS(Tabla3[[#All],[EGRESOS]],Tabla3[[#All],[PERIODO]],Tabla4[[#Headers],[ENERO]],Tabla3[[#All],[ACTIVIDAD]],ACTIVIDADES!$B$16,Tabla3[[#All],[CONCEPTO]],ACTIVIDADES!$B$28,Tabla3[[#All],[DETALLES]],Tabla4[[#This Row],[ACTIVIDADES]]) -> 0 | D30: =SUMIFS(Tabla3[EGRESOS],Tabla3[ACTIVIDAD],ACTIVIDADES!$B$16,Tabla3[PERIODO],Tabla4[[#Headers],[FEBRERO]],Tabla3[CONCEPTO],ACTIVIDADES!B28,Tabla3[DETALLES],Tabla4[[#This Row],[ACTIVIDADES]]) -> 0 | E30: =SUMIFS(Tabla3[[#All],[EGRESOS]],Tabla3[[#All],[PERIODO]],Tabla4[[#Headers],[MARZO]],Tabla3[[#All],[ACTIVIDAD]],ACTIVIDADES!$B$16,Tabla3[[#All],[CONCEPTO]],ACTIVIDADES!$B$28,Tabla3[[#All],[DETALLES]],Tabla4[[#This Row],[ACTIVIDADES]]) -> 0 | F30: =SUMIFS(Tabla3[[#All],[EGRESOS]],Tabla3[[#All],[PERIODO]],Tabla4[[#Headers],[ABRIL]],Tabla3[[#All],[ACTIVIDAD]],ACTIVIDADES!B16,Tabla3[[#All],[CONCEPTO]],ACTIVIDADES!B28,Tabla3[[#All],[DETALLES]],Tabla4[[#This Row],[ACTIVIDADES]]) -> 0 | G30: =SUMIFS(Tabla3[[#All],[EGRESOS]],Tabla3[[#All],[PERIODO]],Tabla4[[#Headers],[MAYO]],Tabla3[[#All],[ACTIVIDAD]],ACTIVIDADES!$B$16,Tabla3[[#All],[CONCEPTO]],ACTIVIDADES!$B$28,Tabla3[[#All],[DETALLES]],Tabla4[[#This Row],[ACTIVIDADES]]) -> 0 | H30: =SUMIFS(Tabla3[[#All],[EGRESOS]],Tabla3[[#All],[PERIODO]],Tabla4[[#Headers],[JUNIO]],Tabla3[[#All],[ACTIVIDAD]],ACTIVIDADES!B16,Tabla3[[#All],[CONCEPTO]],ACTIVIDADES!B28,Tabla3[[#All],[DETALLES]],Tabla4[[#This Row],[ACTIVIDADES]]) -> 0 | I30: =SUMIFS(Tabla3[[#All],[EGRESOS]],Tabla3[[#All],[PERIODO]],Tabla4[[#Headers],[JULIO]],Tabla3[[#All],[ACTIVIDAD]],ACTIVIDADES!B16,Tabla3[[#All],[CONCEPTO]],ACTIVIDADES!B28,Tabla3[[#All],[DETALLES]],Tabla4[[#This Row],[ACTIVIDADES]]) -> 0 | J30: =SUMIFS(Tabla3[[#All],[EGRESOS]],Tabla3[[#All],[PERIODO]],Tabla4[[#Headers],[AGOSTO]],Tabla3[[#All],[ACTIVIDAD]],ACTIVIDADES!B16,Tabla3[[#All],[CONCEPTO]],ACTIVIDADES!B28,Tabla3[[#All],[DETALLES]],Tabla4[[#This Row],[ACTIVIDADES]]) -> 0 | K30: =SUMIFS(Tabla3[[#All],[EGRESOS]],Tabla3[[#All],[PERIODO]],Tabla4[[#Headers],[SEPTIEMBRE]],Tabla3[[#All],[ACTIVIDAD]],ACTIVIDADES!B16,Tabla3[[#All],[CONCEPTO]],ACTIVIDADES!B28,Tabla3[[#All],[DETALLES]],B30) -> 0 | L30: =SUMIFS(Tabla3[[#All],[EGRESOS]],Tabla3[[#All],[PERIODO]],Tabla4[[#Headers],[OCTUBRE]],Tabla3[[#All],[ACTIVIDAD]],$B$16,Tabla3[[#All],[CONCEPTO]],$B$28,Tabla3[[#All],[DETALLES]],B30) -> 0 | M30: =SUMIFS(Tabla3[[#All],[EGRESOS]],Tabla3[[#All],[PERIODO]],Tabla4[[#Headers],[NOVIEMBRE]],Tabla3[[#All],[ACTIVIDAD]],$B$16,Tabla3[[#All],[CONCEPTO]],$B$28,Tabla3[[#All],[DETALLES]],B30) -> 0 | O30: =SUM(Tabla4[[#This Row],[ENERO]:[DICIEMBRE]]) -> 0 | P30: =Tabla4[[#This Row],[USD]]*1140 -> 31920000 | Q30: =Tabla4[[#This Row],[TOTAL]]/Tabla4[[#This Row],[ESTIMADO]] -> 0 | R30: 28000 | S30: =Tabla4[[#This Row],[USD]]/140 -> 200
B31: APLICACIONES | C31: =SUMIFS(Tabla3[[#All],[EGRESOS]],Tabla3[[#All],[PERIODO]],Tabla4[[#Headers],[ENERO]],Tabla3[[#All],[ACTIVIDAD]],ACTIVIDADES!$B$16,Tabla3[[#All],[CONCEPTO]],ACTIVIDADES!$B$28,Tabla3[[#All],[DETALLES]],Tabla4[[#This Row],[ACTIVIDADES]]) -> 0 | D31: =SUMIFS(Tabla3[EGRESOS],Tabla3[ACTIVIDAD],ACTIVIDADES!$B$16,Tabla3[PERIODO],Tabla4[[#Headers],[FEBRERO]],Tabla3[CONCEPTO],ACTIVIDADES!B28,Tabla3[DETALLES],Tabla4[[#This Row],[ACTIVIDADES]]) -> 0 | E31: =SUMIFS(Tabla3[[#All],[EGRESOS]],Tabla3[[#All],[PERIODO]],Tabla4[[#Headers],[MARZO]],Tabla3[[#All],[ACTIVIDAD]],ACTIVIDADES!$B$16,Tabla3[[#All],[CONCEPTO]],ACTIVIDADES!$B$28,Tabla3[[#All],[DETALLES]],Tabla4[[#This Row],[ACTIVIDADES]]) -> 0 | F31: =SUMIFS(Tabla3[[#All],[EGRESOS]],Tabla3[[#All],[PERIODO]],Tabla4[[#Headers],[ABRIL]],Tabla3[[#All],[ACTIVIDAD]],ACTIVIDADES!B16,Tabla3[[#All],[CONCEPTO]],ACTIVIDADES!B28,Tabla3[[#All],[DETALLES]],Tabla4[[#This Row],[ACTIVIDADES]]) -> 0 | G31: =SUMIFS(Tabla3[[#All],[EGRESOS]],Tabla3[[#All],[PERIODO]],Tabla4[[#Headers],[MAYO]],Tabla3[[#All],[ACTIVIDAD]],ACTIVIDADES!$B$16,Tabla3[[#All],[CONCEPTO]],ACTIVIDADES!$B$28,Tabla3[[#All],[DETALLES]],Tabla4[[#This Row],[ACTIVIDADES]]) -> 0 | H31: =SUMIFS(Tabla3[[#All],[EGRESOS]],Tabla3[[#All],[PERIODO]],Tabla4[[#Headers],[JUNIO]],Tabla3[[#All],[ACTIVIDAD]],ACTIVIDADES!B16,Tabla3[[#All],[CONCEPTO]],ACTIVIDADES!B28,Tabla3[[#All],[DETALLES]],Tabla4[[#This Row],[ACTIVIDADES]]) -> 0 | I31: =SUMIFS(Tabla3[[#All],[EGRESOS]],Tabla3[[#All],[PERIODO]],Tabla4[[#Headers],[JULIO]],Tabla3[[#All],[ACTIVIDAD]],ACTIVIDADES!B16,Tabla3[[#All],[CONCEPTO]],ACTIVIDADES!B28,Tabla3[[#All],[DETALLES]],Tabla4[[#This Row],[ACTIVIDADES]]) -> 0 | J31: =SUMIFS(Tabla3[[#All],[EGRESOS]],Tabla3[[#All],[PERIODO]],Tabla4[[#Headers],[AGOSTO]],Tabla3[[#All],[ACTIVIDAD]],ACTIVIDADES!B16,Tabla3[[#All],[CONCEPTO]],ACTIVIDADES!B28,Tabla3[[#All],[DETALLES]],Tabla4[[#This Row],[ACTIVIDADES]]) -> 0 | K31: =SUMIFS(Tabla3[[#All],[EGRESOS]],Tabla3[[#All],[PERIODO]],Tabla4[[#Headers],[SEPTIEMBRE]],Tabla3[[#All],[ACTIVIDAD]],ACTIVIDADES!B16,Tabla3[[#All],[CONCEPTO]],ACTIVIDADES!B28,Tabla3[[#All],[DETALLES]],B31) -> 0 | L31: =SUMIFS(Tabla3[[#All],[EGRESOS]],Tabla3[[#All],[PERIODO]],Tabla4[[#Headers],[OCTUBRE]],Tabla3[[#All],[ACTIVIDAD]],$B$16,Tabla3[[#All],[CONCEPTO]],$B$28,Tabla3[[#All],[DETALLES]],B31) -> 0 | M31: =SUMIFS(Tabla3[[#All],[EGRESOS]],Tabla3[[#All],[PERIODO]],Tabla4[[#Headers],[NOVIEMBRE]],Tabla3[[#All],[ACTIVIDAD]],$B$16,Tabla3[[#All],[CONCEPTO]],$B$28,Tabla3[[#All],[DETALLES]],B31) -> 0 | O31: =SUM(Tabla4[[#This Row],[ENERO]:[DICIEMBRE]]) -> 0 | P31: =Tabla4[[#This Row],[USD]]*1140 -> 5432942.7 | Q31: =Tabla4[[#This Row],[TOTAL]]/Tabla4[[#This Row],[ESTIMADO]] -> 0 | R31: 4765.7392 | S31: =Tabla4[[#This Row],[USD]]/140 -> 34.040994
B32: FLETES FERTILIZANTE | C32: =SUMIFS(Tabla3[[#All],[EGRESOS]],Tabla3[[#All],[PERIODO]],Tabla4[[#Headers],[ENERO]],Tabla3[[#All],[ACTIVIDAD]],ACTIVIDADES!$B$16,Tabla3[[#All],[CONCEPTO]],ACTIVIDADES!$B$28,Tabla3[[#All],[DETALLES]],Tabla4[[#This Row],[ACTIVIDADES]]) -> 0 | D32: =SUMIFS(Tabla3[EGRESOS],Tabla3[ACTIVIDAD],ACTIVIDADES!$B$16,Tabla3[PERIODO],Tabla4[[#Headers],[FEBRERO]],Tabla3[CONCEPTO],ACTIVIDADES!B28,Tabla3[DETALLES],Tabla4[[#This Row],[ACTIVIDADES]]) -> 0 | E32: =SUMIFS(Tabla3[[#All],[EGRESOS]],Tabla3[[#All],[PERIODO]],Tabla4[[#Headers],[MARZO]],Tabla3[[#All],[ACTIVIDAD]],ACTIVIDADES!$B$16,Tabla3[[#All],[CONCEPTO]],ACTIVIDADES!$B$28,Tabla3[[#All],[DETALLES]],Tabla4[[#This Row],[ACTIVIDADES]]) -> 0 | F32: =SUMIFS(Tabla3[[#All],[EGRESOS]],Tabla3[[#All],[PERIODO]],Tabla4[[#Headers],[ABRIL]],Tabla3[[#All],[ACTIVIDAD]],ACTIVIDADES!B16,Tabla3[[#All],[CONCEPTO]],ACTIVIDADES!B28,Tabla3[[#All],[DETALLES]],Tabla4[[#This Row],[ACTIVIDADES]]) -> 0 | G32: =SUMIFS(Tabla3[[#All],[EGRESOS]],Tabla3[[#All],[PERIODO]],Tabla4[[#Headers],[MAYO]],Tabla3[[#All],[ACTIVIDAD]],ACTIVIDADES!$B$16,Tabla3[[#All],[CONCEPTO]],ACTIVIDADES!$B$28,Tabla3[[#All],[DETALLES]],Tabla4[[#This Row],[ACTIVIDADES]]) -> 0 | H32: =SUMIFS(Tabla3[[#All],[EGRESOS]],Tabla3[[#All],[PERIODO]],Tabla4[[#Headers],[JUNIO]],Tabla3[[#All],[ACTIVIDAD]],ACTIVIDADES!B16,Tabla3[[#All],[CONCEPTO]],ACTIVIDADES!B28,Tabla3[[#All],[DETALLES]],Tabla4[[#This Row],[ACTIVIDADES]]) -> 0 | I32: =SUMIFS(Tabla3[[#All],[EGRESOS]],Tabla3[[#All],[PERIODO]],Tabla4[[#Headers],[JULIO]],Tabla3[[#All],[ACTIVIDAD]],ACTIVIDADES!B16,Tabla3[[#All],[CONCEPTO]],ACTIVIDADES!B28,Tabla3[[#All],[DETALLES]],Tabla4[[#This Row],[ACTIVIDADES]]) -> 0 | J32: =SUMIFS(Tabla3[[#All],[EGRESOS]],Tabla3[[#All],[PERIODO]],Tabla4[[#Headers],[AGOSTO]],Tabla3[[#All],[ACTIVIDAD]],ACTIVIDADES!B16,Tabla3[[#All],[CONCEPTO]],ACTIVIDADES!B28,Tabla3[[#All],[DETALLES]],Tabla4[[#This Row],[ACTIVIDADES]]) -> 0 | K32: =SUMIFS(Tabla3[[#All],[EGRESOS]],Tabla3[[#All],[PERIODO]],Tabla4[[#Headers],[SEPTIEMBRE]],Tabla3[[#All],[ACTIVIDAD]],ACTIVIDADES!B16,Tabla3[[#All],[CONCEPTO]],ACTIVIDADES!B28,Tabla3[[#All],[DETALLES]],B32) -> 0 | L32: =SUMIFS(Tabla3[[#All],[EGRESOS]],Tabla3[[#All],[PERIODO]],Tabla4[[#Headers],[OCTUBRE]],Tabla3[[#All],[ACTIVIDAD]],$B$16,Tabla3[[#All],[CONCEPTO]],$B$28,Tabla3[[#All],[DETALLES]],B32) -> 0 | M32: =SUMIFS(Tabla3[[#All],[EGRESOS]],Tabla3[[#All],[PERIODO]],Tabla4[[#Headers],[NOVIEMBRE]],Tabla3[[#All],[ACTIVIDAD]],$B$16,Tabla3[[#All],[CONCEPTO]],$B$28,Tabla3[[#All],[DETALLES]],B32) -> 0 | O32: =SUM(Tabla4[[#This Row],[ENERO]:[DICIEMBRE]]) -> 0 | P32: =Tabla4[[#This Row],[USD]]*1140 -> 500000 | Q32: =Tabla4[[#This Row],[TOTAL]]/Tabla4[[#This Row],[ESTIMADO]] -> 0 | R32: 438.59649 | S32: =Tabla4[[#This Row],[USD]]/140 -> 3.1328321
B33: INSUMOS 2025 | C33: =SUMIFS(Tabla3[[#All],[EGRESOS]],Tabla3[[#All],[PERIODO]],Tabla4[[#Headers],[ENERO]],Tabla3[[#All],[ACTIVIDAD]],ACTIVIDADES!$B$16,Tabla3[[#All],[CONCEPTO]],ACTIVIDADES!$B$28,Tabla3[[#All],[DETALLES]],Tabla4[[#This Row],[ACTIVIDADES]]) -> 0 | D33: =SUMIFS(Tabla3[EGRESOS],Tabla3[ACTIVIDAD],ACTIVIDADES!$B$16,Tabla3[PERIODO],Tabla4[[#Headers],[FEBRERO]],Tabla3[CONCEPTO],ACTIVIDADES!B28,Tabla3[DETALLES],Tabla4[[#This Row],[ACTIVIDADES]]) -> 0 | E33: =SUMIFS(Tabla3[[#All],[EGRESOS]],Tabla3[[#All],[PERIODO]],Tabla4[[#Headers],[MARZO]],Tabla3[[#All],[ACTIVIDAD]],ACTIVIDADES!$B$16,Tabla3[[#All],[CONCEPTO]],ACTIVIDADES!$B$28,Tabla3[[#All],[DETALLES]],Tabla4[[#This Row],[ACTIVIDADES]]) -> 0 | F33: =SUMIFS(Tabla3[[#All],[EGRESOS]],Tabla3[[#All],[PERIODO]],Tabla4[[#Headers],[ABRIL]],Tabla3[[#All],[ACTIVIDAD]],ACTIVIDADES!B16,Tabla3[[#All],[CONCEPTO]],ACTIVIDADES!B28,Tabla3[[#All],[DETALLES]],Tabla4[[#This Row],[ACTIVIDADES]]) -> 0 | G33: =SUMIFS(Tabla3[[#All],[EGRESOS]],Tabla3[[#All],[PERIODO]],Tabla4[[#Headers],[MAYO]],Tabla3[[#All],[ACTIVIDAD]],ACTIVIDADES!$B$16,Tabla3[[#All],[CONCEPTO]],ACTIVIDADES!$B$28,Tabla3[[#All],[DETALLES]],Tabla4[[#This Row],[ACTIVIDADES]]) -> 0 | H33: =SUMIFS(Tabla3[[#All],[EGRESOS]],Tabla3[[#All],[PERIODO]],Tabla4[[#Headers],[JUNIO]],Tabla3[[#All],[ACTIVIDAD]],ACTIVIDADES!B16,Tabla3[[#All],[CONCEPTO]],ACTIVIDADES!B28,Tabla3[[#All],[DETALLES]],Tabla4[[#This Row],[ACTIVIDADES]]) -> 0 | I33: =SUMIFS(Tabla3[[#All],[EGRESOS]],Tabla3[[#All],[PERIODO]],Tabla4[[#Headers],[JULIO]],Tabla3[[#All],[ACTIVIDAD]],ACTIVIDADES!B16,Tabla3[[#All],[CONCEPTO]],ACTIVIDADES!B28,Tabla3[[#All],[DETALLES]],Tabla4[[#This Row],[ACTIVIDADES]]) -> 0 | J33: =SUMIFS(Tabla3[[#All],[EGRESOS]],Tabla3[[#All],[PERIODO]],Tabla4[[#Headers],[AGOSTO]],Tabla3[[#All],[ACTIVIDAD]],ACTIVIDADES!B16,Tabla3[[#All],[CONCEPTO]],ACTIVIDADES!B28,Tabla3[[#All],[DETALLES]],Tabla4[[#This Row],[ACTIVIDADES]]) -> 0 | K33: =SUMIFS(Tabla3[[#All],[EGRESOS]],Tabla3[[#All],[PERIODO]],Tabla4[[#Headers],[SEPTIEMBRE]],Tabla3[[#All],[ACTIVIDAD]],ACTIVIDADES!B16,Tabla3[[#All],[CONCEPTO]],ACTIVIDADES!B28,Tabla3[[#All],[DETALLES]],B33) -> 0 | L33: =SUMIFS(Tabla3[[#All],[EGRESOS]],Tabla3[[#All],[PERIODO]],Tabla4[[#Headers],[OCTUBRE]],Tabla3[[#All],[ACTIVIDAD]],$B$16,Tabla3[[#All],[CONCEPTO]],$B$28,Tabla3[[#All],[DETALLES]],B33) -> 0 | M33: =SUMIFS(Tabla3[[#All],[EGRESOS]],Tabla3[[#All],[PERIODO]],Tabla4[[#Headers],[NOVIEMBRE]],Tabla3[[#All],[ACTIVIDAD]],$B$16,Tabla3[[#All],[CONCEPTO]],$B$28,Tabla3[[#All],[DETALLES]],B33) -> 0 | O33: =SUM(Tabla4[[#This Row],[ENERO]:[DICIEMBRE]]) -> 0 | P33: =Tabla4[[#This Row],[USD]]*1140 -> 56517052 | Q33: =Tabla4[[#This Row],[TOTAL]]/Tabla4[[#This Row],[ESTIMADO]] -> 0 | R33: 49576.362 | S33: =Tabla4[[#This Row],[USD]]/140 -> 354.11687
B34: FLETES | C34: =SUMIFS(Tabla3[[#All],[EGRESOS]],Tabla3[[#All],[PERIODO]],Tabla4[[#Headers],[ENERO]],Tabla3[[#All],[ACTIVIDAD]],ACTIVIDADES!$B$16,Tabla3[[#All],[CONCEPTO]],ACTIVIDADES!$B$28,Tabla3[[#All],[DETALLES]],Tabla4[[#This Row],[ACTIVIDADES]]) -> 0 | D34: =SUMIFS(Tabla3[EGRESOS],Tabla3[ACTIVIDAD],ACTIVIDADES!$B$16,Tabla3[PERIODO],Tabla4[[#Headers],[FEBRERO]],Tabla3[CONCEPTO],ACTIVIDADES!B28,Tabla3[DETALLES],Tabla4[[#This Row],[ACTIVIDADES]]) -> 0 | E34: =SUMIFS(Tabla3[[#All],[EGRESOS]],Tabla3[[#All],[PERIODO]],Tabla4[[#Headers],[MARZO]],Tabla3[[#All],[ACTIVIDAD]],ACTIVIDADES!$B$16,Tabla3[[#All],[CONCEPTO]],ACTIVIDADES!$B$28,Tabla3[[#All],[DETALLES]],Tabla4[[#This Row],[ACTIVIDADES]]) -> 0 | F34: =SUMIFS(Tabla3[[#All],[EGRESOS]],Tabla3[[#All],[PERIODO]],Tabla4[[#Headers],[ABRIL]],Tabla3[[#All],[ACTIVIDAD]],ACTIVIDADES!B16,Tabla3[[#All],[CONCEPTO]],ACTIVIDADES!B28,Tabla3[[#All],[DETALLES]],Tabla4[[#This Row],[ACTIVIDADES]]) -> 0 | G34: =SUMIFS(Tabla3[[#All],[EGRESOS]],Tabla3[[#All],[PERIODO]],Tabla4[[#Headers],[MAYO]],Tabla3[[#All],[ACTIVIDAD]],ACTIVIDADES!$B$16,Tabla3[[#All],[CONCEPTO]],ACTIVIDADES!$B$28,Tabla3[[#All],[DETALLES]],Tabla4[[#This Row],[ACTIVIDADES]]) -> 0 | H34: =SUMIFS(Tabla3[[#All],[EGRESOS]],Tabla3[[#All],[PERIODO]],Tabla4[[#Headers],[JUNIO]],Tabla3[[#All],[ACTIVIDAD]],ACTIVIDADES!B16,Tabla3[[#All],[CONCEPTO]],ACTIVIDADES!B28,Tabla3[[#All],[DETALLES]],Tabla4[[#This Row],[ACTIVIDADES]]) -> 0 | I34: =SUMIFS(Tabla3[[#All],[EGRESOS]],Tabla3[[#All],[PERIODO]],Tabla4[[#Headers],[JULIO]],Tabla3[[#All],[ACTIVIDAD]],ACTIVIDADES!B16,Tabla3[[#All],[CONCEPTO]],ACTIVIDADES!B28,Tabla3[[#All],[DETALLES]],Tabla4[[#This Row],[ACTIVIDADES]]) -> 0 | J34: =SUMIFS(Tabla3[[#All],[EGRESOS]],Tabla3[[#All],[PERIODO]],Tabla4[[#Headers],[AGOSTO]],Tabla3[[#All],[ACTIVIDAD]],ACTIVIDADES!B16,Tabla3[[#All],[CONCEPTO]],ACTIVIDADES!B28,Tabla3[[#All],[DETALLES]],Tabla4[[#This Row],[ACTIVIDADES]]) -> 0 | K34: =SUMIFS(Tabla3[[#All],[EGRESOS]],Tabla3[[#All],[PERIODO]],Tabla4[[#Headers],[SEPTIEMBRE]],Tabla3[[#All],[ACTIVIDAD]],ACTIVIDADES!B16,Tabla3[[#All],[CONCEPTO]],ACTIVIDADES!B28,Tabla3[[#All],[DETALLES]],B34) -> 0 | L34: =SUMIFS(Tabla3[[#All],[EGRESOS]],Tabla3[[#All],[PERIODO]],Tabla4[[#Headers],[OCTUBRE]],Tabla3[[#All],[ACTIVIDAD]],$B$16,Tabla3[[#All],[CONCEPTO]],$B$28,Tabla3[[#All],[DETALLES]],B34) -> 0 | M34: =SUMIFS(Tabla3[[#All],[EGRESOS]],Tabla3[[#All],[PERIODO]],Tabla4[[#Headers],[NOVIEMBRE]],Tabla3[[#All],[ACTIVIDAD]],$B$16,Tabla3[[#All],[CONCEPTO]],$B$28,Tabla3[[#All],[DETALLES]],B34) -> 0 | O34: =SUM(Tabla4[[#This Row],[ENERO]:[DICIEMBRE]]) -> 0 | P34: =Tabla4[[#This Row],[USD]]*1140 -> 38818659 | Q34: =Tabla4[[#This Row],[TOTAL]]/Tabla4[[#This Row],[ESTIMADO]] -> 0 | R34: 34051.456 | S34: =Tabla4[[#This Row],[USD]]/140 -> 243.22468
B35: COSECHA MAIZ | C35: =SUMIFS(Tabla3[[#All],[EGRESOS]],Tabla3[[#All],[PERIODO]],Tabla4[[#Headers],[ENERO]],Tabla3[[#All],[ACTIVIDAD]],ACTIVIDADES!$B$16,Tabla3[[#All],[CONCEPTO]],ACTIVIDADES!$B$28,Tabla3[[#All],[DETALLES]],Tabla4[[#This Row],[ACTIVIDADES]]) -> 0 | D35: =SUMIFS(Tabla3[EGRESOS],Tabla3[ACTIVIDAD],ACTIVIDADES!$B$16,Tabla3[PERIODO],Tabla4[[#Headers],[FEBRERO]],Tabla3[CONCEPTO],ACTIVIDADES!B28,Tabla3[DETALLES],Tabla4[[#This Row],[ACTIVIDADES]]) -> 0 | E35: =SUMIFS(Tabla3[[#All],[EGRESOS]],Tabla3[[#All],[PERIODO]],Tabla4[[#Headers],[MARZO]],Tabla3[[#All],[ACTIVIDAD]],ACTIVIDADES!$B$16,Tabla3[[#All],[CONCEPTO]],ACTIVIDADES!$B$28,Tabla3[[#All],[DETALLES]],Tabla4[[#This Row],[ACTIVIDADES]]) -> 0 | F35: =SUMIFS(Tabla3[[#All],[EGRESOS]],Tabla3[[#All],[PERIODO]],Tabla4[[#Headers],[ABRIL]],Tabla3[[#All],[ACTIVIDAD]],ACTIVIDADES!B16,Tabla3[[#All],[CONCEPTO]],ACTIVIDADES!B28,Tabla3[[#All],[DETALLES]],Tabla4[[#This Row],[ACTIVIDADES]]) -> 0 | G35: =SUMIFS(Tabla3[[#All],[EGRESOS]],Tabla3[[#All],[PERIODO]],Tabla4[[#Headers],[MAYO]],Tabla3[[#All],[ACTIVIDAD]],ACTIVIDADES!$B$16,Tabla3[[#All],[CONCEPTO]],ACTIVIDADES!$B$28,Tabla3[[#All],[DETALLES]],Tabla4[[#This Row],[ACTIVIDADES]]) -> 0 | H35: =SUMIFS(Tabla3[[#All],[EGRESOS]],Tabla3[[#All],[PERIODO]],Tabla4[[#Headers],[JUNIO]],Tabla3[[#All],[ACTIVIDAD]],ACTIVIDADES!B16,Tabla3[[#All],[CONCEPTO]],ACTIVIDADES!B28,Tabla3[[#All],[DETALLES]],Tabla4[[#This Row],[ACTIVIDADES]]) -> 0 | I35: =SUMIFS(Tabla3[[#All],[EGRESOS]],Tabla3[[#All],[PERIODO]],Tabla4[[#Headers],[JULIO]],Tabla3[[#All],[ACTIVIDAD]],ACTIVIDADES!B16,Tabla3[[#All],[CONCEPTO]],ACTIVIDADES!B28,Tabla3[[#All],[DETALLES]],Tabla4[[#This Row],[ACTIVIDADES]]) -> 0 | J35: =SUMIFS(Tabla3[[#All],[EGRESOS]],Tabla3[[#All],[PERIODO]],Tabla4[[#Headers],[AGOSTO]],Tabla3[[#All],[ACTIVIDAD]],ACTIVIDADES!B16,Tabla3[[#All],[CONCEPTO]],ACTIVIDADES!B28,Tabla3[[#All],[DETALLES]],Tabla4[[#This Row],[ACTIVIDADES]]) -> 0 | K35: =SUMIFS(Tabla3[[#All],[EGRESOS]],Tabla3[[#All],[PERIODO]],Tabla4[[#Headers],[SEPTIEMBRE]],Tabla3[[#All],[ACTIVIDAD]],ACTIVIDADES!B16,Tabla3[[#All],[CONCEPTO]],ACTIVIDADES!B28,Tabla3[[#All],[DETALLES]],B35) -> 0 | L35: =SUMIFS(Tabla3[[#All],[EGRESOS]],Tabla3[[#All],[PERIODO]],Tabla4[[#Headers],[OCTUBRE]],Tabla3[[#All],[ACTIVIDAD]],$B$16,Tabla3[[#All],[CONCEPTO]],$B$28,Tabla3[[#All],[DETALLES]],B35) -> 0 | M35: =SUMIFS(Tabla3[[#All],[EGRESOS]],Tabla3[[#All],[PERIODO]],Tabla4[[#Headers],[NOVIEMBRE]],Tabla3[[#All],[ACTIVIDAD]],$B$16,Tabla3[[#All],[CONCEPTO]],$B$28,Tabla3[[#All],[DETALLES]],B35) -> 0 | O35: =SUM(Tabla4[[#This Row],[ENERO]:[DICIEMBRE]]) -> 0 | P35: =Tabla4[[#This Row],[USD]]*1140 -> 13740125 | Q35: =Tabla4[[#This Row],[TOTAL]]/Tabla4[[#This Row],[ESTIMADO]] -> 0 | R35: 12052.741 | S35: =Tabla4[[#This Row],[USD]]/140 -> 86.09101
B36: PICADO | C36: =SUMIFS(Tabla3[[#All],[EGRESOS]],Tabla3[[#All],[PERIODO]],Tabla4[[#Headers],[ENERO]],Tabla3[[#All],[ACTIVIDAD]],ACTIVIDADES!$B$15,Tabla3[[#All],[CONCEPTO]],ACTIVIDADES!$B$28,Tabla3[[#All],[DETALLES]],Tabla4[[#This Row],[ACTIVIDADES]]) -> 0 | D36: =SUMIFS(Tabla3[[#All],[INGRESOS]],Tabla3[[#All],[FECHA]],Tabla4[[#Headers],[FEBRERO]],Tabla3[[#All],[RUBRO]],ACTIVIDADES!$B$15,Tabla3[[#All],[DETALLES]],ACTIVIDADES!$B$28,Tabla3[[#All],[PROVEEDOR CLIENTE]],Tabla4[[#This Row],[ACTIVIDADES]]) -> 0 | E36: =SUMIFS(Tabla3[[#All],[EGRESOS]],Tabla3[[#All],[PERIODO]],Tabla4[[#Headers],[MARZO]],Tabla3[[#All],[ACTIVIDAD]],ACTIVIDADES!B16,Tabla3[[#All],[CONCEPTO]],ACTIVIDADES!B28,Tabla3[[#All],[DETALLES]],Tabla4[[#This Row],[ACTIVIDADES]]) -> 0 | F36: =SUMIFS(Tabla3[[#All],[EGRESOS]],Tabla3[[#All],[PERIODO]],Tabla4[[#Headers],[ABRIL]],Tabla3[[#All],[ACTIVIDAD]],ACTIVIDADES!B16,Tabla3[[#All],[CONCEPTO]],ACTIVIDADES!B28,Tabla3[[#All],[DETALLES]],Tabla4[[#This Row],[ACTIVIDADES]]) -> 0 | G36: =SUMIFS(Tabla3[[#All],[EGRESOS]],Tabla3[[#All],[PERIODO]],Tabla4[[#Headers],[MAYO]],Tabla3[[#All],[ACTIVIDAD]],ACTIVIDADES!B16,Tabla3[[#All],[CONCEPTO]],ACTIVIDADES!B28,Tabla3[[#All],[DETALLES]],Tabla4[[#This Row],[ACTIVIDADES]]) -> 0 | H36: =SUMIFS(Tabla3[[#All],[EGRESOS]],Tabla3[[#All],[PERIODO]],Tabla4[[#Headers],[JUNIO]],Tabla3[[#All],[ACTIVIDAD]],ACTIVIDADES!B16,Tabla3[[#All],[CONCEPTO]],ACTIVIDADES!B28,Tabla3[[#All],[DETALLES]],Tabla4[[#This Row],[ACTIVIDADES]]) -> 0 | I36: =SUMIFS(Tabla3[[#All],[EGRESOS]],Tabla3[[#All],[PERIODO]],Tabla4[[#Headers],[JULIO]],Tabla3[[#All],[ACTIVIDAD]],ACTIVIDADES!B16,Tabla3[[#All],[CONCEPTO]],ACTIVIDADES!B28,Tabla3[[#All],[DETALLES]],Tabla4[[#This Row],[ACTIVIDADES]]) -> 0 | J36: =SUMIFS(Tabla3[[#All],[EGRESOS]],Tabla3[[#All],[PERIODO]],Tabla4[[#Headers],[AGOSTO]],Tabla3[[#All],[ACTIVIDAD]],ACTIVIDADES!B16,Tabla3[[#All],[CONCEPTO]],ACTIVIDADES!B28,Tabla3[[#All],[DETALLES]],Tabla4[[#This Row],[ACTIVIDADES]]) -> 0 | K36: =SUMIFS(Tabla3[[#All],[EGRESOS]],Tabla3[[#All],[PERIODO]],Tabla4[[#Headers],[SEPTIEMBRE]],Tabla3[[#All],[ACTIVIDAD]],ACTIVIDADES!B16,Tabla3[[#All],[CONCEPTO]],ACTIVIDADES!B28,Tabla3[[#All],[DETALLES]],B36) -> 0 | L36: =SUMIFS(Tabla3[[#All],[EGRESOS]],Tabla3[[#All],[PERIODO]],Tabla4[[#Headers],[OCTUBRE]],Tabla3[[#All],[ACTIVIDAD]],$B$16,Tabla3[[#All],[CONCEPTO]],$B$28,Tabla3[[#All],[DETALLES]],B36) -> 0 | M36: =SUMIFS(Tabla3[[#All],[EGRESOS]],Tabla3[[#All],[PERIODO]],Tabla4[[#Headers],[NOVIEMBRE]],Tabla3[[#All],[ACTIVIDAD]],$B$16,Tabla3[[#All],[CONCEPTO]],$B$28,Tabla3[[#All],[DETALLES]],B36) -> 0 | O36: =SUM(Tabla4[[#This Row],[ENERO]:[DICIEMBRE]]) -> 0 | P36: =Tabla4[[#This Row],[USD]]*1400 -> 29400000 | Q36: =Tabla4[[#This Row],[TOTAL]]/Tabla4[[#This Row],[ESTIMADO]] -> 0 | R36: 21000 | S36: =Tabla4[[#This Row],[USD]]/140 -> 150
B37: ACARREO | K37: =SUMIFS(Tabla3[[#All],[EGRESOS]],Tabla3[[#All],[PERIODO]],Tabla4[[#Headers],[SEPTIEMBRE]],Tabla3[[#All],[ACTIVIDAD]],ACTIVIDADES!B16,Tabla3[[#All],[CONCEPTO]],ACTIVIDADES!B28,Tabla3[[#All],[DETALLES]],B37) -> 0 | L37: =SUMIFS(Tabla3[[#All],[EGRESOS]],Tabla3[[#All],[PERIODO]],Tabla4[[#Headers],[OCTUBRE]],Tabla3[[#All],[ACTIVIDAD]],$B$16,Tabla3[[#All],[CONCEPTO]],$B$28,Tabla3[[#All],[DETALLES]],B37) -> 0 | M37: =SUMIFS(Tabla3[[#All],[EGRESOS]],Tabla3[[#All],[PERIODO]],Tabla4[[#Headers],[NOVIEMBRE]],Tabla3[[#All],[ACTIVIDAD]],$B$16,Tabla3[[#All],[CONCEPTO]],$B$28,Tabla3[[#All],[DETALLES]],B37) -> 0 | O37: =SUM(Tabla4[[#This Row],[ENERO]:[DICIEMBRE]]) -> 0 | P37: =Tabla4[[#This Row],[USD]]*1400 -> 280000 | Q37: =Tabla4[[#This Row],[TOTAL]]/Tabla4[[#This Row],[ESTIMADO]] -> 0 | R37: 200 | S37: =Tabla4[[#This Row],[USD]]/140 -> 1.4285714
B38: GANADERIA | C38: =SUBTOTAL(109,C39:C43) -> 1187657.1 | D38: =SUBTOTAL(109,D39:D43) -> 1370600 | E38: =SUBTOTAL(109,E39:E43) -> 0 | F38: =SUBTOTAL(109,F39:F43) -> 0 | G38: =SUBTOTAL(109,G39:G43) -> 0 | H38: =SUBTOTAL(109,H39:H43) -> 0 | I38: =SUBTOTAL(109,I39:I43) -> 0 | J38: =SUBTOTAL(109,J39:J43) -> 0 | ... P38: =SUBTOTAL(109,P39:P43) -> 448600000 | Q38: =Tabla4[[#This Row],[TOTAL]]/Tabla4[[#This Row],[ESTIMADO]] -> 0.0057027577 | R38: =SUBTOTAL(109,R39:R43) -> 383418.8
B39: VETERINARIA | C39: =SUMIFS(Tabla3[[#All],[EGRESOS]],Tabla3[[#All],[PERIODO]],Tabla4[[#Headers],[ENERO]],Tabla3[[#All],[ACTIVIDAD]],ACTIVIDADES!B38,Tabla3[[#All],[CONCEPTO]],Tabla4[[#This Row],[ACTIVIDADES]]) -> 570657.08 | D39: =SUMIFS(Tabla3[EGRESOS],Tabla3[ACTIVIDAD],ACTIVIDADES!$B$38,Tabla3[CONCEPTO],ACTIVIDADES!B39,Tabla3[PERIODO],Tabla4[[#Headers],[FEBRERO]]) -> 662600.02 | E39: =SUMIFS(Tabla3[[#All],[EGRESOS]],Tabla3[[#All],[PERIODO]],Tabla4[[#Headers],[MARZO]],Tabla3[[#All],[ACTIVIDAD]],ACTIVIDADES!B38,Tabla3[[#All],[CONCEPTO]],Tabla4[[#This Row],[ACTIVIDADES]]) -> 0 | F39: =SUMIFS(Tabla3[[#All],[EGRESOS]],Tabla3[[#All],[PERIODO]],Tabla4[[#Headers],[ABRIL]],Tabla3[[#All],[ACTIVIDAD]],ACTIVIDADES!B38,Tabla3[[#All],[CONCEPTO]],Tabla4[[#This Row],[ACTIVIDADES]]) -> 0 | G39: =SUMIFS(Tabla3[[#All],[EGRESOS]],Tabla3[[#All],[PERIODO]],Tabla4[[#Headers],[MAYO]],Tabla3[[#All],[ACTIVIDAD]],ACTIVIDADES!B38,Tabla3[[#All],[CONCEPTO]],Tabla4[[#This Row],[ACTIVIDADES]]) -> 0 | H39: =SUMIFS(Tabla3[[#All],[EGRESOS]],Tabla3[[#All],[PERIODO]],Tabla4[[#Headers],[JUNIO]],Tabla3[[#All],[ACTIVIDAD]],ACTIVIDADES!B38,Tabla3[[#All],[CONCEPTO]],Tabla4[[#This Row],[ACTIVIDADES]]) -> 0 | I39: =SUMIFS(Tabla3[[#All],[EGRESOS]],Tabla3[[#All],[PERIODO]],Tabla4[[#Headers],[JULIO]],Tabla3[[#All],[ACTIVIDAD]],ACTIVIDADES!B38,Tabla3[[#All],[CONCEPTO]],Tabla4[[#This Row],[ACTIVIDADES]]) -> 0 | J39: =SUMIFS(Tabla3[[#All],[EGRESOS]],Tabla3[[#All],[PERIODO]],Tabla4[[#Headers],[AGOSTO]],Tabla3[[#All],[ACTIVIDAD]],ACTIVIDADES!B38,Tabla3[[#All],[CONCEPTO]],Tabla4[[#This Row],[ACTIVIDADES]]) -> 0 | K39: =SUMIFS(Tabla3[[#All],[EGRESOS]],Tabla3[[#All],[PERIODO]],Tabla4[[#Headers],[SEPTIEMBRE]],Tabla3[[#All],[ACTIVIDAD]],ACTIVIDADES!B38,Tabla3[[#All],[CONCEPTO]],Tabla4[[#This Row],[ACTIVIDADES]]) -> 0 | L39: =SUMIFS(Tabla3[[#All],[EGRESOS]],Tabla3[[#All],[PERIODO]],Tabla4[[#Headers],[OCTUBRE]],Tabla3[[#All],[ACTIVIDAD]],$B$38,Tabla3[[#All],[CONCEPTO]],Tabla4[[#This Row],[ACTIVIDADES]]) -> 0 | M39: =SUMIFS(Tabla3[[#All],[EGRESOS]],Tabla3[[#All],[PERIODO]],Tabla4[[#Headers],[NOVIEMBRE]],Tabla3[[#All],[ACTIVIDAD]],$B$38,Tabla3[[#All],[CONCEPTO]],Tabla4[[#This Row],[ACTIVIDADES]]) -> 0 | O39: =SUM(Tabla4[[#This Row],[ENERO]:[DICIEMBRE]]) -> 1233257.1 | P39: 8000000 | Q39: =Tabla4[[#This Row],[TOTAL]]/Tabla4[[#This Row],[ESTIMADO]] -> 0.15415714 | R39: =Tabla4[[#This Row],[ESTIMADO]]/1170 -> 6837.6068
B40: LABORATORIO | C40: =SUMIFS(Tabla3[[#All],[EGRESOS]],Tabla3[[#All],[PERIODO]],Tabla4[[#Headers],[ENERO]],Tabla3[[#All],[ACTIVIDAD]],ACTIVIDADES!B38,Tabla3[[#All],[CONCEPTO]],Tabla4[[#This Row],[ACTIVIDADES]]) -> 0 | D40: =SUMIFS(Tabla3[EGRESOS],Tabla3[ACTIVIDAD],ACTIVIDADES!$B$38,Tabla3[CONCEPTO],ACTIVIDADES!B40,Tabla3[PERIODO],Tabla4[[#Headers],[FEBRERO]]) -> 48000 | E40: =SUMIFS(Tabla3[[#All],[EGRESOS]],Tabla3[[#All],[PERIODO]],Tabla4[[#Headers],[MARZO]],Tabla3[[#All],[ACTIVIDAD]],ACTIVIDADES!B38,Tabla3[[#All],[CONCEPTO]],Tabla4[[#This Row],[ACTIVIDADES]]) -> 0 | F40: =SUMIFS(Tabla3[[#All],[EGRESOS]],Tabla3[[#All],[PERIODO]],Tabla4[[#Headers],[ABRIL]],Tabla3[[#All],[ACTIVIDAD]],ACTIVIDADES!B38,Tabla3[[#All],[CONCEPTO]],Tabla4[[#This Row],[ACTIVIDADES]]) -> 0 | G40: =SUMIFS(Tabla3[[#All],[EGRESOS]],Tabla3[[#All],[PERIODO]],Tabla4[[#Headers],[MAYO]],Tabla3[[#All],[ACTIVIDAD]],ACTIVIDADES!B38,Tabla3[[#All],[CONCEPTO]],Tabla4[[#This Row],[ACTIVIDADES]]) -> 0 | H40: =SUMIFS(Tabla3[[#All],[EGRESOS]],Tabla3[[#All],[PERIODO]],Tabla4[[#Headers],[JUNIO]],Tabla3[[#All],[ACTIVIDAD]],ACTIVIDADES!B38,Tabla3[[#All],[CONCEPTO]],Tabla4[[#This Row],[ACTIVIDADES]]) -> 0 | I40: =SUMIFS(Tabla3[[#All],[EGRESOS]],Tabla3[[#All],[PERIODO]],Tabla4[[#Headers],[JULIO]],Tabla3[[#All],[ACTIVIDAD]],ACTIVIDADES!B38,Tabla3[[#All],[CONCEPTO]],Tabla4[[#This Row],[ACTIVIDADES]]) -> 0 | J40: =SUMIFS(Tabla3[[#All],[EGRESOS]],Tabla3[[#All],[PERIODO]],Tabla4[[#Headers],[AGOSTO]],Tabla3[[#All],[ACTIVIDAD]],ACTIVIDADES!B38,Tabla3[[#All],[CONCEPTO]],Tabla4[[#This Row],[ACTIVIDADES]]) -> 0 | K40: =SUMIFS(Tabla3[[#All],[EGRESOS]],Tabla3[[#All],[PERIODO]],Tabla4[[#Headers],[SEPTIEMBRE]],Tabla3[[#All],[ACTIVIDAD]],ACTIVIDADES!B38,Tabla3[[#All],[CONCEPTO]],Tabla4[[#This Row],[ACTIVIDADES]]) -> 0 | L40: =SUMIFS(Tabla3[[#All],[EGRESOS]],Tabla3[[#All],[PERIODO]],Tabla4[[#Headers],[OCTUBRE]],Tabla3[[#All],[ACTIVIDAD]],$B$38,Tabla3[[#All],[CONCEPTO]],Tabla4[[#This Row],[ACTIVIDADES]]) -> 0 | M40: =SUMIFS(Tabla3[[#All],[EGRESOS]],Tabla3[[#All],[PERIODO]],Tabla4[[#Headers],[NOVIEMBRE]],Tabla3[[#All],[ACTIVIDAD]],$B$38,Tabla3[[#All],[CONCEPTO]],Tabla4[[#This Row],[ACTIVIDADES]]) -> 0 | O40: =SUM(Tabla4[[#This Row],[ENERO]:[DICIEMBRE]]) -> 48000 | P40: 100000 | Q40: =Tabla4[[#This Row],[TOTAL]]/Tabla4[[#This Row],[ESTIMADO]] -> 0.48 | R40: =Tabla4[[#This Row],[ESTIMADO]]/1170 -> 85.470085
